Workbook

Sheet ⚡ COMMAND TRACKER
A1: ⚡ eCON GROWTH · COMMAND OS COLD CALL INTELLIGENCE · POWERED BY SECONDBRAIN AI
A2: 🏢 COMPANY INTEL | I2: 📞 CALL INTELLIGENCE | O2: 🔥 PAIN MATRIX | U2: 🎯 CONVERSION | Y2: 🤖 AI FIT ENGINE | AB2: 📅 FOLLOW-UP SYSTEM
A3: Company Name | B3: Phone | C3: City | D3: Website | E3: Owner / DM | F3: Contact Name | G3: Role | H3: # Trucks | I3: Answer Status | J3: Person Reached | K3: DM Reached? | L3: Opening Reaction | M3: Main Pain | N3: Call Notes | O3: Recruiting Pain | P3: Retention Pain | Q3: Ops/System Pain | R3: Revenue Pain | S3: Pain Detail | T3: Pain Score | U3: Open to Meeting? | V3: Meeting Type | W3: Objection | X3: Follow-Up Action | Y3: Fit Score | Z3: Fit Tier | AA3: Priority | AB3: Last Call | AC3: Callback Date | AD3: Days Until Call | AE3: Caller
T5: =IFERROR(ROUND((IF(O5="Severe",4,IF(O5="Moderate",3,IF(O5="Minor",2,0)))+IF(P5="Severe",4,IF(P5="Moderate",3,IF(P5="Minor",2,0)))+IF(Q5="Severe",4,IF(Q5="Moderate",3,IF(Q5="Minor",2,0)))+IF(R5="Severe",4,IF(R5="Moderate",3,IF(R5="Minor",2,0))))/16*100,0),"") -> 0 | Y5: =IFERROR(ROUND(IF(H5>=10,30,IF(H5>=5,20,IF(H5>=2,10,0)))+IF(K5="Yes",20,IF(K5="Unsure",10,0))+IF(U5="Yes",30,IF(U5="Later",15,0))+IFERROR(T5/100*20,0),0),"") -> 0 | Z5: =IFERROR(IF(Y5>=80,"🔥 HOT",IF(Y5>=60,"✅ STRONG",IF(Y5>=40,"⚡ WARM",IF(Y5>=20,"📋 NURTURE",IF(Y5>0,"❌ COLD",""))))),"") | AA5: =IFERROR(IF(AND(Y5>=60,OR(U5="Yes",U5="Later")),"🚨 URGENT",IF(AND(Y5>=40,I5="Call Back"),"📞 CALL BACK",IF(I5="Booked Meeting","📅 BOOKED",IF(I5="Not Interested","🚫 DEAD","⏳ WORKING")))),"") -> ⏳ WORKING | AD5: =IFERROR(IF(AC5="","",AC5-TODAY()),"")
T6: =IFERROR(ROUND((IF(O6="Severe",4,IF(O6="Moderate",3,IF(O6="Minor",2,0)))+IF(P6="Severe",4,IF(P6="Moderate",3,IF(P6="Minor",2,0)))+IF(Q6="Severe",4,IF(Q6="Moderate",3,IF(Q6="Minor",2,0)))+IF(R6="Severe",4,IF(R6="Moderate",3,IF(R6="Minor",2,0))))/16*100,0),"") -> 0 | Y6: =IFERROR(ROUND(IF(H6>=10,30,IF(H6>=5,20,IF(H6>=2,10,0)))+IF(K6="Yes",20,IF(K6="Unsure",10,0))+IF(U6="Yes",30,IF(U6="Later",15,0))+IFERROR(T6/100*20,0),0),"") -> 0 | Z6: =IFERROR(IF(Y6>=80,"🔥 HOT",IF(Y6>=60,"✅ STRONG",IF(Y6>=40,"⚡ WARM",IF(Y6>=20,"📋 NURTURE",IF(Y6>0,"❌ COLD",""))))),"") | AA6: =IFERROR(IF(AND(Y6>=60,OR(U6="Yes",U6="Later")),"🚨 URGENT",IF(AND(Y6>=40,I6="Call Back"),"📞 CALL BACK",IF(I6="Booked Meeting","📅 BOOKED",IF(I6="Not Interested","🚫 DEAD","⏳ WORKING")))),"") -> ⏳ WORKING | AD6: =IFERROR(IF(AC6="","",AC6-TODAY()),"")
T7: =IFERROR(ROUND((IF(O7="Severe",4,IF(O7="Moderate",3,IF(O7="Minor",2,0)))+IF(P7="Severe",4,IF(P7="Moderate",3,IF(P7="Minor",2,0)))+IF(Q7="Severe",4,IF(Q7="Moderate",3,IF(Q7="Minor",2,0)))+IF(R7="Severe",4,IF(R7="Moderate",3,IF(R7="Minor",2,0))))/16*100,0),"") -> 0 | Y7: =IFERROR(ROUND(IF(H7>=10,30,IF(H7>=5,20,IF(H7>=2,10,0)))+IF(K7="Yes",20,IF(K7="Unsure",10,0))+IF(U7="Yes",30,IF(U7="Later",15,0))+IFERROR(T7/100*20,0),0),"") -> 0 | Z7: =IFERROR(IF(Y7>=80,"🔥 HOT",IF(Y7>=60,"✅ STRONG",IF(Y7>=40,"⚡ WARM",IF(Y7>=20,"📋 NURTURE",IF(Y7>0,"❌ COLD",""))))),"") | AA7: =IFERROR(IF(AND(Y7>=60,OR(U7="Yes",U7="Later")),"🚨 URGENT",IF(AND(Y7>=40,I7="Call Back"),"📞 CALL BACK",IF(I7="Booked Meeting","📅 BOOKED",IF(I7="Not Interested","🚫 DEAD","⏳ WORKING")))),"") -> ⏳ WORKING | AD7: =IFERROR(IF(AC7="","",AC7-TODAY()),"")
T8: =IFERROR(ROUND((IF(O8="Severe",4,IF(O8="Moderate",3,IF(O8="Minor",2,0)))+IF(P8="Severe",4,IF(P8="Moderate",3,IF(P8="Minor",2,0)))+IF(Q8="Severe",4,IF(Q8="Moderate",3,IF(Q8="Minor",2,0)))+IF(R8="Severe",4,IF(R8="Moderate",3,IF(R8="Minor",2,0))))/16*100,0),"") -> 0 | Y8: =IFERROR(ROUND(IF(H8>=10,30,IF(H8>=5,20,IF(H8>=2,10,0)))+IF(K8="Yes",20,IF(K8="Unsure",10,0))+IF(U8="Yes",30,IF(U8="Later",15,0))+IFERROR(T8/100*20,0),0),"") -> 0 | Z8: =IFERROR(IF(Y8>=80,"🔥 HOT",IF(Y8>=60,"✅ STRONG",IF(Y8>=40,"⚡ WARM",IF(Y8>=20,"📋 NURTURE",IF(Y8>0,"❌ COLD",""))))),"") | AA8: =IFERROR(IF(AND(Y8>=60,OR(U8="Yes",U8="Later")),"🚨 URGENT",IF(AND(Y8>=40,I8="Call Back"),"📞 CALL BACK",IF(I8="Booked Meeting","📅 BOOKED",IF(I8="Not Interested","🚫 DEAD","⏳ WORKING")))),"") -> ⏳ WORKING | AD8: =IFERROR(IF(AC8="","",AC8-TODAY()),"")
T9: =IFERROR(ROUND((IF(O9="Severe",4,IF(O9="Moderate",3,IF(O9="Minor",2,0)))+IF(P9="Severe",4,IF(P9="Moderate",3,IF(P9="Minor",2,0)))+IF(Q9="Severe",4,IF(Q9="Moderate",3,IF(Q9="Minor",2,0)))+IF(R9="Severe",4,IF(R9="Moderate",3,IF(R9="Minor",2,0))))/16*100,0),"") -> 0 | Y9: =IFERROR(ROUND(IF(H9>=10,30,IF(H9>=5,20,IF(H9>=2,10,0)))+IF(K9="Yes",20,IF(K9="Unsure",10,0))+IF(U9="Yes",30,IF(U9="Later",15,0))+IFERROR(T9/100*20,0),0),"") -> 0 | Z9: =IFERROR(IF(Y9>=80,"🔥 HOT",IF(Y9>=60,"✅ STRONG",IF(Y9>=40,"⚡ WARM",IF(Y9>=20,"📋 NURTURE",IF(Y9>0,"❌ COLD",""))))),"") | AA9: =IFERROR(IF(AND(Y9>=60,OR(U9="Yes",U9="Later")),"🚨 URGENT",IF(AND(Y9>=40,I9="Call Back"),"📞 CALL BACK",IF(I9="Booked Meeting","📅 BOOKED",IF(I9="Not Interested","🚫 DEAD","⏳ WORKING")))),"") -> ⏳ WORKING | AD9: =IFERROR(IF(AC9="","",AC9-TODAY()),"")
T10: =IFERROR(ROUND((IF(O10="Severe",4,IF(O10="Moderate",3,IF(O10="Minor",2,0)))+IF(P10="Severe",4,IF(P10="Moderate",3,IF(P10="Minor",2,0)))+IF(Q10="Severe",4,IF(Q10="Moderate",3,IF(Q10="Minor",2,0)))+IF(R10="Severe",4,IF(R10="Moderate",3,IF(R10="Minor",2,0))))/16*100,0),"") -> 0 | Y10: =IFERROR(ROUND(IF(H10>=10,30,IF(H10>=5,20,IF(H10>=2,10,0)))+IF(K10="Yes",20,IF(K10="Unsure",10,0))+IF(U10="Yes",30,IF(U10="Later",15,0))+IFERROR(T10/100*20,0),0),"") -> 0 | Z10: =IFERROR(IF(Y10>=80,"🔥 HOT",IF(Y10>=60,"✅ STRONG",IF(Y10>=40,"⚡ WARM",IF(Y10>=20,"📋 NURTURE",IF(Y10>0,"❌ COLD",""))))),"") | AA10: =IFERROR(IF(AND(Y10>=60,OR(U10="Yes",U10="Later")),"🚨 URGENT",IF(AND(Y10>=40,I10="Call Back"),"📞 CALL BACK",IF(I10="Booked Meeting","📅 BOOKED",IF(I10="Not Interested","🚫 DEAD","⏳ WORKING")))),"") -> ⏳ WORKING | AD10: =IFERROR(IF(AC10="","",AC10-TODAY()),"")
T11: =IFERROR(ROUND((IF(O11="Severe",4,IF(O11="Moderate",3,IF(O11="Minor",2,0)))+IF(P11="Severe",4,IF(P11="Moderate",3,IF(P11="Minor",2,0)))+IF(Q11="Severe",4,IF(Q11="Moderate",3,IF(Q11="Minor",2,0)))+IF(R11="Severe",4,IF(R11="Moderate",3,IF(R11="Minor",2,0))))/16*100,0),"") -> 0 | Y11: =IFERROR(ROUND(IF(H11>=10,30,IF(H11>=5,20,IF(H11>=2,10,0)))+IF(K11="Yes",20,IF(K11="Unsure",10,0))+IF(U11="Yes",30,IF(U11="Later",15,0))+IFERROR(T11/100*20,0),0),"") -> 0 | Z11: =IFERROR(IF(Y11>=80,"🔥 HOT",IF(Y11>=60,"✅ STRONG",IF(Y11>=40,"⚡ WARM",IF(Y11>=20,"📋 NURTURE",IF(Y11>0,"❌ COLD",""))))),"") | AA11: =IFERROR(IF(AND(Y11>=60,OR(U11="Yes",U11="Later")),"🚨 URGENT",IF(AND(Y11>=40,I11="Call Back"),"📞 CALL BACK",IF(I11="Booked Meeting","📅 BOOKED",IF(I11="Not Interested","🚫 DEAD","⏳ WORKING")))),"") -> ⏳ WORKING | AD11: =IFERROR(IF(AC11="","",AC11-TODAY()),"")
T12: =IFERROR(ROUND((IF(O12="Severe",4,IF(O12="Moderate",3,IF(O12="Minor",2,0)))+IF(P12="Severe",4,IF(P12="Moderate",3,IF(P12="Minor",2,0)))+IF(Q12="Severe",4,IF(Q12="Moderate",3,IF(Q12="Minor",2,0)))+IF(R12="Severe",4,IF(R12="Moderate",3,IF(R12="Minor",2,0))))/16*100,0),"") -> 0 | Y12: =IFERROR(ROUND(IF(H12>=10,30,IF(H12>=5,20,IF(H12>=2,10,0)))+IF(K12="Yes",20,IF(K12="Unsure",10,0))+IF(U12="Yes",30,IF(U12="Later",15,0))+IFERROR(T12/100*20,0),0),"") -> 0 | Z12: =IFERROR(IF(Y12>=80,"🔥 HOT",IF(Y12>=60,"✅ STRONG",IF(Y12>=40,"⚡ WARM",IF(Y12>=20,"📋 NURTURE",IF(Y12>0,"❌ COLD",""))))),"") | AA12: =IFERROR(IF(AND(Y12>=60,OR(U12="Yes",U12="Later")),"🚨 URGENT",IF(AND(Y12>=40,I12="Call Back"),"📞 CALL BACK",IF(I12="Booked Meeting","📅 BOOKED",IF(I12="Not Interested","🚫 DEAD","⏳ WORKING")))),"") -> ⏳ WORKING | AD12: =IFERROR(IF(AC12="","",AC12-TODAY()),"")
T13: =IFERROR(ROUND((IF(O13="Severe",4,IF(O13="Moderate",3,IF(O13="Minor",2,0)))+IF(P13="Severe",4,IF(P13="Moderate",3,IF(P13="Minor",2,0)))+IF(Q13="Severe",4,IF(Q13="Moderate",3,IF(Q13="Minor",2,0)))+IF(R13="Severe",4,IF(R13="Moderate",3,IF(R13="Minor",2,0))))/16*100,0),"") -> 0 | Y13: =IFERROR(ROUND(IF(H13>=10,30,IF(H13>=5,20,IF(H13>=2,10,0)))+IF(K13="Yes",20,IF(K13="Unsure",10,0))+IF(U13="Yes",30,IF(U13="Later",15,0))+IFERROR(T13/100*20,0),0),"") -> 0 | Z13: =IFERROR(IF(Y13>=80,"🔥 HOT",IF(Y13>=60,"✅ STRONG",IF(Y13>=40,"⚡ WARM",IF(Y13>=20,"📋 NURTURE",IF(Y13>0,"❌ COLD",""))))),"") | AA13: =IFERROR(IF(AND(Y13>=60,OR(U13="Yes",U13="Later")),"🚨 URGENT",IF(AND(Y13>=40,I13="Call Back"),"📞 CALL BACK",IF(I13="Booked Meeting","📅 BOOKED",IF(I13="Not Interested","🚫 DEAD","⏳ WORKING")))),"") -> ⏳ WORKING | AD13: =IFERROR(IF(AC13="","",AC13-TODAY()),"")
T14: =IFERROR(ROUND((IF(O14="Severe",4,IF(O14="Moderate",3,IF(O14="Minor",2,0)))+IF(P14="Severe",4,IF(P14="Moderate",3,IF(P14="Minor",2,0)))+IF(Q14="Severe",4,IF(Q14="Moderate",3,IF(Q14="Minor",2,0)))+IF(R14="Severe",4,IF(R14="Moderate",3,IF(R14="Minor",2,0))))/16*100,0),"") -> 0 | Y14: =IFERROR(ROUND(IF(H14>=10,30,IF(H14>=5,20,IF(H14>=2,10,0)))+IF(K14="Yes",20,IF(K14="Unsure",10,0))+IF(U14="Yes",30,IF(U14="Later",15,0))+IFERROR(T14/100*20,0),0),"") -> 0 | Z14: =IFERROR(IF(Y14>=80,"🔥 HOT",IF(Y14>=60,"✅ STRONG",IF(Y14>=40,"⚡ WARM",IF(Y14>=20,"📋 NURTURE",IF(Y14>0,"❌ COLD",""))))),"") | AA14: =IFERROR(IF(AND(Y14>=60,OR(U14="Yes",U14="Later")),"🚨 URGENT",IF(AND(Y14>=40,I14="Call Back"),"📞 CALL BACK",IF(I14="Booked Meeting","📅 BOOKED",IF(I14="Not Interested","🚫 DEAD","⏳ WORKING")))),"") -> ⏳ WORKING | AD14: =IFERROR(IF(AC14="","",AC14-TODAY()),"")
T15: =IFERROR(ROUND((IF(O15="Severe",4,IF(O15="Moderate",3,IF(O15="Minor",2,0)))+IF(P15="Severe",4,IF(P15="Moderate",3,IF(P15="Minor",2,0)))+IF(Q15="Severe",4,IF(Q15="Moderate",3,IF(Q15="Minor",2,0)))+IF(R15="Severe",4,IF(R15="Moderate",3,IF(R15="Minor",2,0))))/16*100,0),"") -> 0 | Y15: =IFERROR(ROUND(IF(H15>=10,30,IF(H15>=5,20,IF(H15>=2,10,0)))+IF(K15="Yes",20,IF(K15="Unsure",10,0))+IF(U15="Yes",30,IF(U15="Later",15,0))+IFERROR(T15/100*20,0),0),"") -> 0 | Z15: =IFERROR(IF(Y15>=80,"🔥 HOT",IF(Y15>=60,"✅ STRONG",IF(Y15>=40,"⚡ WARM",IF(Y15>=20,"📋 NURTURE",IF(Y15>0,"❌ COLD",""))))),"") | AA15: =IFERROR(IF(AND(Y15>=60,OR(U15="Yes",U15="Later")),"🚨 URGENT",IF(AND(Y15>=40,I15="Call Back"),"📞 CALL BACK",IF(I15="Booked Meeting","📅 BOOKED",IF(I15="Not Interested","🚫 DEAD","⏳ WORKING")))),"") -> ⏳ WORKING | AD15: =IFERROR(IF(AC15="","",AC15-TODAY()),"")
T16: =IFERROR(ROUND((IF(O16="Severe",4,IF(O16="Moderate",3,IF(O16="Minor",2,0)))+IF(P16="Severe",4,IF(P16="Moderate",3,IF(P16="Minor",2,0)))+IF(Q16="Severe",4,IF(Q16="Moderate",3,IF(Q16="Minor",2,0)))+IF(R16="Severe",4,IF(R16="Moderate",3,IF(R16="Minor",2,0))))/16*100,0),"") -> 0 | Y16: =IFERROR(ROUND(IF(H16>=10,30,IF(H16>=5,20,IF(H16>=2,10,0)))+IF(K16="Yes",20,IF(K16="Unsure",10,0))+IF(U16="Yes",30,IF(U16="Later",15,0))+IFERROR(T16/100*20,0),0),"") -> 0 | Z16: =IFERROR(IF(Y16>=80,"🔥 HOT",IF(Y16>=60,"✅ STRONG",IF(Y16>=40,"⚡ WARM",IF(Y16>=20,"📋 NURTURE",IF(Y16>0,"❌ COLD",""))))),"") | AA16: =IFERROR(IF(AND(Y16>=60,OR(U16="Yes",U16="Later")),"🚨 URGENT",IF(AND(Y16>=40,I16="Call Back"),"📞 CALL BACK",IF(I16="Booked Meeting","📅 BOOKED",IF(I16="Not Interested","🚫 DEAD","⏳ WORKING")))),"") -> ⏳ WORKING | AD16: =IFERROR(IF(AC16="","",AC16-TODAY()),"")
... T204: =IFERROR(ROUND((IF(O204="Severe",4,IF(O204="Moderate",3,IF(O204="Minor",2,0)))+IF(P204="Severe",4,IF(P204="Moderate",3,IF(P204="Minor",2,0)))+IF(Q204="Severe",4,IF(Q204="Moderate",3,IF(Q204="Minor",2,0)))+IF(R204="Severe",4,IF(R204="Moderate",3,IF(R204="Minor",2,0))))/16*100,0),"") -> 0 | Y204: =IFERROR(ROUND(IF(H204>=10,30,IF(H204>=5,20,IF(H204>=2,10,0)))+IF(K204="Yes",20,IF(K204="Unsure",10,0))+IF(U204="Yes",30,IF(U204="Later",15,0))+IFERROR(T204/100*20,0),0),"") -> 0 | Z204: =IFERROR(IF(Y204>=80,"🔥 HOT",IF(Y204>=60,"✅ STRONG",IF(Y204>=40,"⚡ WARM",IF(Y204>=20,"📋 NURTURE",IF(Y204>0,"❌ COLD",""))))),"") | AA204: =IFERROR(IF(AND(Y204>=60,OR(U204="Yes",U204="Later")),"🚨 URGENT",IF(AND(Y204>=40,I204="Call Back"),"📞 CALL BACK",IF(I204="Booked Meeting","📅 BOOKED",IF(I204="Not Interested","🚫 DEAD","⏳ WORKING")))),"") -> ⏳ WORKING | AD204: =IFERROR(IF(AC204="","",AC204-TODAY()),"")

Sheet 🔥 HOT LEADS
A1: 🔥 HOT LEADS · FIT SCORE ≥ 60 · AUTO-PULLED FROM COMMAND TRACKER
A2: These leads are auto-ranked. Work them top-down. Update the Callback Date and they'll appear in your Follow-Up Engine.
A3: Priority | B3: Company | C3: Owner/DM | D3: Phone | E3: # Trucks | F3: Fit Score | G3: Fit Tier | H3: Pain Score | I3: Open to Meeting? | J3: Follow-Up Action | K3: Callback Date | L3: Days Until | M3: Caller
A4: =IFERROR(INDEX('⚡ COMMAND TRACKER'!$AA$5:$AA$204,MATCH(LARGE('⚡ COMMAND TRACKER'!$Y$5:$Y$204,1),'⚡ COMMAND TRACKER'!$Y$5:$Y$204,0)),"") -> ⏳ WORKING | B4: =IFERROR(INDEX('⚡ COMMAND TRACKER'!$A$5:$A$204,MATCH(LARGE('⚡ COMMAND TRACKER'!$Y$5:$Y$204,1),'⚡ COMMAND TRACKER'!$Y$5:$Y$204,0)),"") -> 0 | C4: =IFERROR(INDEX('⚡ COMMAND TRACKER'!$E$5:$E$204,MATCH(LARGE('⚡ COMMAND TRACKER'!$Y$5:$Y$204,1),'⚡ COMMAND TRACKER'!$Y$5:$Y$204,0)),"") -> 0 | D4: =IFERROR(INDEX('⚡ COMMAND TRACKER'!$B$5:$B$204,MATCH(LARGE('⚡ COMMAND TRACKER'!$Y$5:$Y$204,1),'⚡ COMMAND TRACKER'!$Y$5:$Y$204,0)),"") -> 0 | E4: =IFERROR(INDEX('⚡ COMMAND TRACKER'!$H$5:$H$204,MATCH(LARGE('⚡ COMMAND TRACKER'!$Y$5:$Y$204,1),'⚡ COMMAND TRACKER'!$Y$5:$Y$204,0)),"") -> 0 | F4: =IFERROR(LARGE('⚡ COMMAND TRACKER'!$Y$5:$Y$204,1),"") -> 0 | G4: =IFERROR(INDEX('⚡ COMMAND TRACKER'!$Z$5:$Z$204,MATCH(LARGE('⚡ COMMAND TRACKER'!$Y$5:$Y$204,1),'⚡ COMMAND TRACKER'!$Y$5:$Y$204,0)),"") | H4: =IFERROR(INDEX('⚡ COMMAND TRACKER'!$T$5:$T$204,MATCH(LARGE('⚡ COMMAND TRACKER'!$Y$5:$Y$204,1),'⚡ COMMAND TRACKER'!$Y$5:$Y$204,0)),"") -> 0 | I4: =IFERROR(INDEX('⚡ COMMAND TRACKER'!$U$5:$U$204,MATCH(LARGE('⚡ COMMAND TRACKER'!$Y$5:$Y$204,1),'⚡ COMMAND TRACKER'!$Y$5:$Y$204,0)),"") -> 0 | J4: =IFERROR(INDEX('⚡ COMMAND TRACKER'!$X$5:$X$204,MATCH(LARGE('⚡ COMMAND TRACKER'!$Y$5:$Y$204,1),'⚡ COMMAND TRACKER'!$Y$5:$Y$204,0)),"") -> 0 | K4: =IFERROR(INDEX('⚡ COMMAND TRACKER'!$AC$5:$AC$204,MATCH(LARGE('⚡ COMMAND TRACKER'!$Y$5:$Y$204,1),'⚡ COMMAND TRACKER'!$Y$5:$Y$204,0)),"") -> 0 | L4: =IFERROR(IF(K4="","",K4-TODAY()),"") | M4: =IFERROR(INDEX('⚡ COMMAND TRACKER'!$AE$5:$AE$204,MATCH(LARGE('⚡ COMMAND TRACKER'!$Y$5:$Y$204,1),'⚡ COMMAND TRACKER'!$Y$5:$Y$204,0)),"") -> 0
A5: =IFERROR(INDEX('⚡ COMMAND TRACKER'!$AA$5:$AA$204,MATCH(LARGE('⚡ COMMAND TRACKER'!$Y$5:$Y$204,2),'⚡ COMMAND TRACKER'!$Y$5:$Y$204,0)),"") -> ⏳ WORKING | B5: =IFERROR(INDEX('⚡ COMMAND TRACKER'!$A$5:$A$204,MATCH(LARGE('⚡ COMMAND TRACKER'!$Y$5:$Y$204,2),'⚡ COMMAND TRACKER'!$Y$5:$Y$204,0)),"") -> 0 | C5: =IFERROR(INDEX('⚡ COMMAND TRACKER'!$E$5:$E$204,MATCH(LARGE('⚡ COMMAND TRACKER'!$Y$5:$Y$204,2),'⚡ COMMAND TRACKER'!$Y$5:$Y$204,0)),"") -> 0 | D5: =IFERROR(INDEX('⚡ COMMAND TRACKER'!$B$5:$B$204,MATCH(LARGE('⚡ COMMAND TRACKER'!$Y$5:$Y$204,2),'⚡ COMMAND TRACKER'!$Y$5:$Y$204,0)),"") -> 0 | E5: =IFERROR(INDEX('⚡ COMMAND TRACKER'!$H$5:$H$204,MATCH(LARGE('⚡ COMMAND TRACKER'!$Y$5:$Y$204,2),'⚡ COMMAND TRACKER'!$Y$5:$Y$204,0)),"") -> 0 | F5: =IFERROR(LARGE('⚡ COMMAND TRACKER'!$Y$5:$Y$204,2),"") -> 0 | G5: =IFERROR(INDEX('⚡ COMMAND TRACKER'!$Z$5:$Z$204,MATCH(LARGE('⚡ COMMAND TRACKER'!$Y$5:$Y$204,2),'⚡ COMMAND TRACKER'!$Y$5:$Y$204,0)),"") | H5: =IFERROR(INDEX('⚡ COMMAND TRACKER'!$T$5:$T$204,MATCH(LARGE('⚡ COMMAND TRACKER'!$Y$5:$Y$204,2),'⚡ COMMAND TRACKER'!$Y$5:$Y$204,0)),"") -> 0 | I5: =IFERROR(INDEX('⚡ COMMAND TRACKER'!$U$5:$U$204,MATCH(LARGE('⚡ COMMAND TRACKER'!$Y$5:$Y$204,2),'⚡ COMMAND TRACKER'!$Y$5:$Y$204,0)),"") -> 0 | J5: =IFERROR(INDEX('⚡ COMMAND TRACKER'!$X$5:$X$204,MATCH(LARGE('⚡ COMMAND TRACKER'!$Y$5:$Y$204,2),'⚡ COMMAND TRACKER'!$Y$5:$Y$204,0)),"") -> 0 | K5: =IFERROR(INDEX('⚡ COMMAND TRACKER'!$AC$5:$AC$204,MATCH(LARGE('⚡ COMMAND TRACKER'!$Y$5:$Y$204,2),'⚡ COMMAND TRACKER'!$Y$5:$Y$204,0)),"") -> 0 | L5: =IFERROR(IF(K5="","",K5-TODAY()),"") | M5: =IFERROR(INDEX('⚡ COMMAND TRACKER'!$AE$5:$AE$204,MATCH(LARGE('⚡ COMMAND TRACKER'!$Y$5:$Y$204,2),'⚡ COMMAND TRACKER'!$Y$5:$Y$204,0)),"") -> 0
A6: =IFERROR(INDEX('⚡ COMMAND TRACKER'!$AA$5:$AA$204,MATCH(LARGE('⚡ COMMAND TRACKER'!$Y$5:$Y$204,3),'⚡ COMMAND TRACKER'!$Y$5:$Y$204,0)),"") -> ⏳ WORKING | B6: =IFERROR(INDEX('⚡ COMMAND TRACKER'!$A$5:$A$204,MATCH(LARGE('⚡ COMMAND TRACKER'!$Y$5:$Y$204,3),'⚡ COMMAND TRACKER'!$Y$5:$Y$204,0)),"") -> 0 | C6: =IFERROR(INDEX('⚡ COMMAND TRACKER'!$E$5:$E$204,MATCH(LARGE('⚡ COMMAND TRACKER'!$Y$5:$Y$204,3),'⚡ COMMAND TRACKER'!$Y$5:$Y$204,0)),"") -> 0 | D6: =IFERROR(INDEX('⚡ COMMAND TRACKER'!$B$5:$B$204,MATCH(LARGE('⚡ COMMAND TRACKER'!$Y$5:$Y$204,3),'⚡ COMMAND TRACKER'!$Y$5:$Y$204,0)),"") -> 0 | E6: =IFERROR(INDEX('⚡ COMMAND TRACKER'!$H$5:$H$204,MATCH(LARGE('⚡ COMMAND TRACKER'!$Y$5:$Y$204,3),'⚡ COMMAND TRACKER'!$Y$5:$Y$204,0)),"") -> 0 | F6: =IFERROR(LARGE('⚡ COMMAND TRACKER'!$Y$5:$Y$204,3),"") -> 0 | G6: =IFERROR(INDEX('⚡ COMMAND TRACKER'!$Z$5:$Z$204,MATCH(LARGE('⚡ COMMAND TRACKER'!$Y$5:$Y$204,3),'⚡ COMMAND TRACKER'!$Y$5:$Y$204,0)),"") | H6: =IFERROR(INDEX('⚡ COMMAND TRACKER'!$T$5:$T$204,MATCH(LARGE('⚡ COMMAND TRACKER'!$Y$5:$Y$204,3),'⚡ COMMAND TRACKER'!$Y$5:$Y$204,0)),"") -> 0 | I6: =IFERROR(INDEX('⚡ COMMAND TRACKER'!$U$5:$U$204,MATCH(LARGE('⚡ COMMAND TRACKER'!$Y$5:$Y$204,3),'⚡ COMMAND TRACKER'!$Y$5:$Y$204,0)),"") -> 0 | J6: =IFERROR(INDEX('⚡ COMMAND TRACKER'!$X$5:$X$204,MATCH(LARGE('⚡ COMMAND TRACKER'!$Y$5:$Y$204,3),'⚡ COMMAND TRACKER'!$Y$5:$Y$204,0)),"") -> 0 | K6: =IFERROR(INDEX('⚡ COMMAND TRACKER'!$AC$5:$AC$204,MATCH(LARGE('⚡ COMMAND TRACKER'!$Y$5:$Y$204,3),'⚡ COMMAND TRACKER'!$Y$5:$Y$204,0)),"") -> 0 | L6: =IFERROR(IF(K6="","",K6-TODAY()),"") | M6: =IFERROR(INDEX('⚡ COMMAND TRACKER'!$AE$5:$AE$204,MATCH(LARGE('⚡ COMMAND TRACKER'!$Y$5:$Y$204,3),'⚡ COMMAND TRACKER'!$Y$5:$Y$204,0)),"") -> 0
A7: =IFERROR(INDEX('⚡ COMMAND TRACKER'!$AA$5:$AA$204,MATCH(LARGE('⚡ COMMAND TRACKER'!$Y$5:$Y$204,4),'⚡ COMMAND TRACKER'!$Y$5:$Y$204,0)),"") -> ⏳ WORKING | B7: =IFERROR(INDEX('⚡ COMMAND TRACKER'!$A$5:$A$204,MATCH(LARGE('⚡ COMMAND TRACKER'!$Y$5:$Y$204,4),'⚡ COMMAND TRACKER'!$Y$5:$Y$204,0)),"") -> 0 | C7: =IFERROR(INDEX('⚡ COMMAND TRACKER'!$E$5:$E$204,MATCH(LARGE('⚡ COMMAND TRACKER'!$Y$5:$Y$204,4),'⚡ COMMAND TRACKER'!$Y$5:$Y$204,0)),"") -> 0 | D7: =IFERROR(INDEX('⚡ COMMAND TRACKER'!$B$5:$B$204,MATCH(LARGE('⚡ COMMAND TRACKER'!$Y$5:$Y$204,4),'⚡ COMMAND TRACKER'!$Y$5:$Y$204,0)),"") -> 0 | E7: =IFERROR(INDEX('⚡ COMMAND TRACKER'!$H$5:$H$204,MATCH(LARGE('⚡ COMMAND TRACKER'!$Y$5:$Y$204,4),'⚡ COMMAND TRACKER'!$Y$5:$Y$204,0)),"") -> 0 | F7: =IFERROR(LARGE('⚡ COMMAND TRACKER'!$Y$5:$Y$204,4),"") -> 0 | G7: =IFERROR(INDEX('⚡ COMMAND TRACKER'!$Z$5:$Z$204,MATCH(LARGE('⚡ COMMAND TRACKER'!$Y$5:$Y$204,4),'⚡ COMMAND TRACKER'!$Y$5:$Y$204,0)),"") | H7: =IFERROR(INDEX('⚡ COMMAND TRACKER'!$T$5:$T$204,MATCH(LARGE('⚡ COMMAND TRACKER'!$Y$5:$Y$204,4),'⚡ COMMAND TRACKER'!$Y$5:$Y$204,0)),"") -> 0 | I7: =IFERROR(INDEX('⚡ COMMAND TRACKER'!$U$5:$U$204,MATCH(LARGE('⚡ COMMAND TRACKER'!$Y$5:$Y$204,4),'⚡ COMMAND TRACKER'!$Y$5:$Y$204,0)),"") -> 0 | J7: =IFERROR(INDEX('⚡ COMMAND TRACKER'!$X$5:$X$204,MATCH(LARGE('⚡ COMMAND TRACKER'!$Y$5:$Y$204,4),'⚡ COMMAND TRACKER'!$Y$5:$Y$204,0)),"") -> 0 | K7: =IFERROR(INDEX('⚡ COMMAND TRACKER'!$AC$5:$AC$204,MATCH(LARGE('⚡ COMMAND TRACKER'!$Y$5:$Y$204,4),'⚡ COMMAND TRACKER'!$Y$5:$Y$204,0)),"") -> 0 | L7: =IFERROR(IF(K7="","",K7-TODAY()),"") | M7: =IFERROR(INDEX('⚡ COMMAND TRACKER'!$AE$5:$AE$204,MATCH(LARGE('⚡ COMMAND TRACKER'!$Y$5:$Y$204,4),'⚡ COMMAND TRACKER'!$Y$5:$Y$204,0)),"") -> 0
A8: =IFERROR(INDEX('⚡ COMMAND TRACKER'!$AA$5:$AA$204,MATCH(LARGE('⚡ COMMAND TRACKER'!$Y$5:$Y$204,5),'⚡ COMMAND TRACKER'!$Y$5:$Y$204,0)),"") -> ⏳ WORKING | B8: =IFERROR(INDEX('⚡ COMMAND TRACKER'!$A$5:$A$204,MATCH(LARGE('⚡ COMMAND TRACKER'!$Y$5:$Y$204,5),'⚡ COMMAND TRACKER'!$Y$5:$Y$204,0)),"") -> 0 | C8: =IFERROR(INDEX('⚡ COMMAND TRACKER'!$E$5:$E$204,MATCH(LARGE('⚡ COMMAND TRACKER'!$Y$5:$Y$204,5),'⚡ COMMAND TRACKER'!$Y$5:$Y$204,0)),"") -> 0 | D8: =IFERROR(INDEX('⚡ COMMAND TRACKER'!$B$5:$B$204,MATCH(LARGE('⚡ COMMAND TRACKER'!$Y$5:$Y$204,5),'⚡ COMMAND TRACKER'!$Y$5:$Y$204,0)),"") -> 0 | E8: =IFERROR(INDEX('⚡ COMMAND TRACKER'!$H$5:$H$204,MATCH(LARGE('⚡ COMMAND TRACKER'!$Y$5:$Y$204,5),'⚡ COMMAND TRACKER'!$Y$5:$Y$204,0)),"") -> 0 | F8: =IFERROR(LARGE('⚡ COMMAND TRACKER'!$Y$5:$Y$204,5),"") -> 0 | G8: =IFERROR(INDEX('⚡ COMMAND TRACKER'!$Z$5:$Z$204,MATCH(LARGE('⚡ COMMAND TRACKER'!$Y$5:$Y$204,5),'⚡ COMMAND TRACKER'!$Y$5:$Y$204,0)),"") | H8: =IFERROR(INDEX('⚡ COMMAND TRACKER'!$T$5:$T$204,MATCH(LARGE('⚡ COMMAND TRACKER'!$Y$5:$Y$204,5),'⚡ COMMAND TRACKER'!$Y$5:$Y$204,0)),"") -> 0 | I8: =IFERROR(INDEX('⚡ COMMAND TRACKER'!$U$5:$U$204,MATCH(LARGE('⚡ COMMAND TRACKER'!$Y$5:$Y$204,5),'⚡ COMMAND TRACKER'!$Y$5:$Y$204,0)),"") -> 0 | J8: =IFERROR(INDEX('⚡ COMMAND TRACKER'!$X$5:$X$204,MATCH(LARGE('⚡ COMMAND TRACKER'!$Y$5:$Y$204,5),'⚡ COMMAND TRACKER'!$Y$5:$Y$204,0)),"") -> 0 | K8: =IFERROR(INDEX('⚡ COMMAND TRACKER'!$AC$5:$AC$204,MATCH(LARGE('⚡ COMMAND TRACKER'!$Y$5:$Y$204,5),'⚡ COMMAND TRACKER'!$Y$5:$Y$204,0)),"") -> 0 | L8: =IFERROR(IF(K8="","",K8-TODAY()),"") | M8: =IFERROR(INDEX('⚡ COMMAND TRACKER'!$AE$5:$AE$204,MATCH(LARGE('⚡ COMMAND TRACKER'!$Y$5:$Y$204,5),'⚡ COMMAND TRACKER'!$Y$5:$Y$204,0)),"") -> 0
A9: =IFERROR(INDEX('⚡ COMMAND TRACKER'!$AA$5:$AA$204,MATCH(LARGE('⚡ COMMAND TRACKER'!$Y$5:$Y$204,6),'⚡ COMMAND TRACKER'!$Y$5:$Y$204,0)),"") -> ⏳ WORKING | B9: =IFERROR(INDEX('⚡ COMMAND TRACKER'!$A$5:$A$204,MATCH(LARGE('⚡ COMMAND TRACKER'!$Y$5:$Y$204,6),'⚡ COMMAND TRACKER'!$Y$5:$Y$204,0)),"") -> 0 | C9: =IFERROR(INDEX('⚡ COMMAND TRACKER'!$E$5:$E$204,MATCH(LARGE('⚡ COMMAND TRACKER'!$Y$5:$Y$204,6),'⚡ COMMAND TRACKER'!$Y$5:$Y$204,0)),"") -> 0 | D9: =IFERROR(INDEX('⚡ COMMAND TRACKER'!$B$5:$B$204,MATCH(LARGE('⚡ COMMAND TRACKER'!$Y$5:$Y$204,6),'⚡ COMMAND TRACKER'!$Y$5:$Y$204,0)),"") -> 0 | E9: =IFERROR(INDEX('⚡ COMMAND TRACKER'!$H$5:$H$204,MATCH(LARGE('⚡ COMMAND TRACKER'!$Y$5:$Y$204,6),'⚡ COMMAND TRACKER'!$Y$5:$Y$204,0)),"") -> 0 | F9: =IFERROR(LARGE('⚡ COMMAND TRACKER'!$Y$5:$Y$204,6),"") -> 0 | G9: =IFERROR(INDEX('⚡ COMMAND TRACKER'!$Z$5:$Z$204,MATCH(LARGE('⚡ COMMAND TRACKER'!$Y$5:$Y$204,6),'⚡ COMMAND TRACKER'!$Y$5:$Y$204,0)),"") | H9: =IFERROR(INDEX('⚡ COMMAND TRACKER'!$T$5:$T$204,MATCH(LARGE('⚡ COMMAND TRACKER'!$Y$5:$Y$204,6),'⚡ COMMAND TRACKER'!$Y$5:$Y$204,0)),"") -> 0 | I9: =IFERROR(INDEX('⚡ COMMAND TRACKER'!$U$5:$U$204,MATCH(LARGE('⚡ COMMAND TRACKER'!$Y$5:$Y$204,6),'⚡ COMMAND TRACKER'!$Y$5:$Y$204,0)),"") -> 0 | J9: =IFERROR(INDEX('⚡ COMMAND TRACKER'!$X$5:$X$204,MATCH(LARGE('⚡ COMMAND TRACKER'!$Y$5:$Y$204,6),'⚡ COMMAND TRACKER'!$Y$5:$Y$204,0)),"") -> 0 | K9: =IFERROR(INDEX('⚡ COMMAND TRACKER'!$AC$5:$AC$204,MATCH(LARGE('⚡ COMMAND TRACKER'!$Y$5:$Y$204,6),'⚡ COMMAND TRACKER'!$Y$5:$Y$204,0)),"") -> 0 | L9: =IFERROR(IF(K9="","",K9-TODAY()),"") | M9: =IFERROR(INDEX('⚡ COMMAND TRACKER'!$AE$5:$AE$204,MATCH(LARGE('⚡ COMMAND TRACKER'!$Y$5:$Y$204,6),'⚡ COMMAND TRACKER'!$Y$5:$Y$204,0)),"") -> 0
A10: =IFERROR(INDEX('⚡ COMMAND TRACKER'!$AA$5:$AA$204,MATCH(LARGE('⚡ COMMAND TRACKER'!$Y$5:$Y$204,7),'⚡ COMMAND TRACKER'!$Y$5:$Y$204,0)),"") -> ⏳ WORKING | B10: =IFERROR(INDEX('⚡ COMMAND TRACKER'!$A$5:$A$204,MATCH(LARGE('⚡ COMMAND TRACKER'!$Y$5:$Y$204,7),'⚡ COMMAND TRACKER'!$Y$5:$Y$204,0)),"") -> 0 | C10: =IFERROR(INDEX('⚡ COMMAND TRACKER'!$E$5:$E$204,MATCH(LARGE('⚡ COMMAND TRACKER'!$Y$5:$Y$204,7),'⚡ COMMAND TRACKER'!$Y$5:$Y$204,0)),"") -> 0 | D10: =IFERROR(INDEX('⚡ COMMAND TRACKER'!$B$5:$B$204,MATCH(LARGE('⚡ COMMAND TRACKER'!$Y$5:$Y$204,7),'⚡ COMMAND TRACKER'!$Y$5:$Y$204,0)),"") -> 0 | E10: =IFERROR(INDEX('⚡ COMMAND TRACKER'!$H$5:$H$204,MATCH(LARGE('⚡ COMMAND TRACKER'!$Y$5:$Y$204,7),'⚡ COMMAND TRACKER'!$Y$5:$Y$204,0)),"") -> 0 | F10: =IFERROR(LARGE('⚡ COMMAND TRACKER'!$Y$5:$Y$204,7),"") -> 0 | G10: =IFERROR(INDEX('⚡ COMMAND TRACKER'!$Z$5:$Z$204,MATCH(LARGE('⚡ COMMAND TRACKER'!$Y$5:$Y$204,7),'⚡ COMMAND TRACKER'!$Y$5:$Y$204,0)),"") | H10: =IFERROR(INDEX('⚡ COMMAND TRACKER'!$T$5:$T$204,MATCH(LARGE('⚡ COMMAND TRACKER'!$Y$5:$Y$204,7),'⚡ COMMAND TRACKER'!$Y$5:$Y$204,0)),"") -> 0 | I10: =IFERROR(INDEX('⚡ COMMAND TRACKER'!$U$5:$U$204,MATCH(LARGE('⚡ COMMAND TRACKER'!$Y$5:$Y$204,7),'⚡ COMMAND TRACKER'!$Y$5:$Y$204,0)),"") -> 0 | J10: =IFERROR(INDEX('⚡ COMMAND TRACKER'!$X$5:$X$204,MATCH(LARGE('⚡ COMMAND TRACKER'!$Y$5:$Y$204,7),'⚡ COMMAND TRACKER'!$Y$5:$Y$204,0)),"") -> 0 | K10: =IFERROR(INDEX('⚡ COMMAND TRACKER'!$AC$5:$AC$204,MATCH(LARGE('⚡ COMMAND TRACKER'!$Y$5:$Y$204,7),'⚡ COMMAND TRACKER'!$Y$5:$Y$204,0)),"") -> 0 | L10: =IFERROR(IF(K10="","",K10-TODAY()),"") | M10: =IFERROR(INDEX('⚡ COMMAND TRACKER'!$AE$5:$AE$204,MATCH(LARGE('⚡ COMMAND TRACKER'!$Y$5:$Y$204,7),'⚡ COMMAND TRACKER'!$Y$5:$Y$204,0)),"") -> 0
A11: =IFERROR(INDEX('⚡ COMMAND TRACKER'!$AA$5:$AA$204,MATCH(LARGE('⚡ COMMAND TRACKER'!$Y$5:$Y$204,8),'⚡ COMMAND TRACKER'!$Y$5:$Y$204,0)),"") -> ⏳ WORKING | B11: =IFERROR(INDEX('⚡ COMMAND TRACKER'!$A$5:$A$204,MATCH(LARGE('⚡ COMMAND TRACKER'!$Y$5:$Y$204,8),'⚡ COMMAND TRACKER'!$Y$5:$Y$204,0)),"") -> 0 | C11: =IFERROR(INDEX('⚡ COMMAND TRACKER'!$E$5:$E$204,MATCH(LARGE('⚡ COMMAND TRACKER'!$Y$5:$Y$204,8),'⚡ COMMAND TRACKER'!$Y$5:$Y$204,0)),"") -> 0 | D11: =IFERROR(INDEX('⚡ COMMAND TRACKER'!$B$5:$B$204,MATCH(LARGE('⚡ COMMAND TRACKER'!$Y$5:$Y$204,8),'⚡ COMMAND TRACKER'!$Y$5:$Y$204,0)),"") -> 0 | E11: =IFERROR(INDEX('⚡ COMMAND TRACKER'!$H$5:$H$204,MATCH(LARGE('⚡ COMMAND TRACKER'!$Y$5:$Y$204,8),'⚡ COMMAND TRACKER'!$Y$5:$Y$204,0)),"") -> 0 | F11: =IFERROR(LARGE('⚡ COMMAND TRACKER'!$Y$5:$Y$204,8),"") -> 0 | G11: =IFERROR(INDEX('⚡ COMMAND TRACKER'!$Z$5:$Z$204,MATCH(LARGE('⚡ COMMAND TRACKER'!$Y$5:$Y$204,8),'⚡ COMMAND TRACKER'!$Y$5:$Y$204,0)),"") | H11: =IFERROR(INDEX('⚡ COMMAND TRACKER'!$T$5:$T$204,MATCH(LARGE('⚡ COMMAND TRACKER'!$Y$5:$Y$204,8),'⚡ COMMAND TRACKER'!$Y$5:$Y$204,0)),"") -> 0 | I11: =IFERROR(INDEX('⚡ COMMAND TRACKER'!$U$5:$U$204,MATCH(LARGE('⚡ COMMAND TRACKER'!$Y$5:$Y$204,8),'⚡ COMMAND TRACKER'!$Y$5:$Y$204,0)),"") -> 0 | J11: =IFERROR(INDEX('⚡ COMMAND TRACKER'!$X$5:$X$204,MATCH(LARGE('⚡ COMMAND TRACKER'!$Y$5:$Y$204,8),'⚡ COMMAND TRACKER'!$Y$5:$Y$204,0)),"") -> 0 | K11: =IFERROR(INDEX('⚡ COMMAND TRACKER'!$AC$5:$AC$204,MATCH(LARGE('⚡ COMMAND TRACKER'!$Y$5:$Y$204,8),'⚡ COMMAND TRACKER'!$Y$5:$Y$204,0)),"") -> 0 | L11: =IFERROR(IF(K11="","",K11-TODAY()),"") | M11: =IFERROR(INDEX('⚡ COMMAND TRACKER'!$AE$5:$AE$204,MATCH(LARGE('⚡ COMMAND TRACKER'!$Y$5:$Y$204,8),'⚡ COMMAND TRACKER'!$Y$5:$Y$204,0)),"") -> 0
A12: =IFERROR(INDEX('⚡ COMMAND TRACKER'!$AA$5:$AA$204,MATCH(LARGE('⚡ COMMAND TRACKER'!$Y$5:$Y$204,9),'⚡ COMMAND TRACKER'!$Y$5:$Y$204,0)),"") -> ⏳ WORKING | B12: =IFERROR(INDEX('⚡ COMMAND TRACKER'!$A$5:$A$204,MATCH(LARGE('⚡ COMMAND TRACKER'!$Y$5:$Y$204,9),'⚡ COMMAND TRACKER'!$Y$5:$Y$204,0)),"") -> 0 | C12: =IFERROR(INDEX('⚡ COMMAND TRACKER'!$E$5:$E$204,MATCH(LARGE('⚡ COMMAND TRACKER'!$Y$5:$Y$204,9),'⚡ COMMAND TRACKER'!$Y$5:$Y$204,0)),"") -> 0 | D12: =IFERROR(INDEX('⚡ COMMAND TRACKER'!$B$5:$B$204,MATCH(LARGE('⚡ COMMAND TRACKER'!$Y$5:$Y$204,9),'⚡ COMMAND TRACKER'!$Y$5:$Y$204,0)),"") -> 0 | E12: =IFERROR(INDEX('⚡ COMMAND TRACKER'!$H$5:$H$204,MATCH(LARGE('⚡ COMMAND TRACKER'!$Y$5:$Y$204,9),'⚡ COMMAND TRACKER'!$Y$5:$Y$204,0)),"") -> 0 | F12: =IFERROR(LARGE('⚡ COMMAND TRACKER'!$Y$5:$Y$204,9),"") -> 0 | G12: =IFERROR(INDEX('⚡ COMMAND TRACKER'!$Z$5:$Z$204,MATCH(LARGE('⚡ COMMAND TRACKER'!$Y$5:$Y$204,9),'⚡ COMMAND TRACKER'!$Y$5:$Y$204,0)),"") | H12: =IFERROR(INDEX('⚡ COMMAND TRACKER'!$T$5:$T$204,MATCH(LARGE('⚡ COMMAND TRACKER'!$Y$5:$Y$204,9),'⚡ COMMAND TRACKER'!$Y$5:$Y$204,0)),"") -> 0 | I12: =IFERROR(INDEX('⚡ COMMAND TRACKER'!$U$5:$U$204,MATCH(LARGE('⚡ COMMAND TRACKER'!$Y$5:$Y$204,9),'⚡ COMMAND TRACKER'!$Y$5:$Y$204,0)),"") -> 0 | J12: =IFERROR(INDEX('⚡ COMMAND TRACKER'!$X$5:$X$204,MATCH(LARGE('⚡ COMMAND TRACKER'!$Y$5:$Y$204,9),'⚡ COMMAND TRACKER'!$Y$5:$Y$204,0)),"") -> 0 | K12: =IFERROR(INDEX('⚡ COMMAND TRACKER'!$AC$5:$AC$204,MATCH(LARGE('⚡ COMMAND TRACKER'!$Y$5:$Y$204,9),'⚡ COMMAND TRACKER'!$Y$5:$Y$204,0)),"") -> 0 | L12: =IFERROR(IF(K12="","",K12-TODAY()),"") | M12: =IFERROR(INDEX('⚡ COMMAND TRACKER'!$AE$5:$AE$204,MATCH(LARGE('⚡ COMMAND TRACKER'!$Y$5:$Y$204,9),'⚡ COMMAND TRACKER'!$Y$5:$Y$204,0)),"") -> 0
A13: =IFERROR(INDEX('⚡ COMMAND TRACKER'!$AA$5:$AA$204,MATCH(LARGE('⚡ COMMAND TRACKER'!$Y$5:$Y$204,10),'⚡ COMMAND TRACKER'!$Y$5:$Y$204,0)),"") -> ⏳ WORKING | B13: =IFERROR(INDEX('⚡ COMMAND TRACKER'!$A$5:$A$204,MATCH(LARGE('⚡ COMMAND TRACKER'!$Y$5:$Y$204,10),'⚡ COMMAND TRACKER'!$Y$5:$Y$204,0)),"") -> 0 | C13: =IFERROR(INDEX('⚡ COMMAND TRACKER'!$E$5:$E$204,MATCH(LARGE('⚡ COMMAND TRACKER'!$Y$5:$Y$204,10),'⚡ COMMAND TRACKER'!$Y$5:$Y$204,0)),"") -> 0 | D13: =IFERROR(INDEX('⚡ COMMAND TRACKER'!$B$5:$B$204,MATCH(LARGE('⚡ COMMAND TRACKER'!$Y$5:$Y$204,10),'⚡ COMMAND TRACKER'!$Y$5:$Y$204,0)),"") -> 0 | E13: =IFERROR(INDEX('⚡ COMMAND TRACKER'!$H$5:$H$204,MATCH(LARGE('⚡ COMMAND TRACKER'!$Y$5:$Y$204,10),'⚡ COMMAND TRACKER'!$Y$5:$Y$204,0)),"") -> 0 | F13: =IFERROR(LARGE('⚡ COMMAND TRACKER'!$Y$5:$Y$204,10),"") -> 0 | G13: =IFERROR(INDEX('⚡ COMMAND TRACKER'!$Z$5:$Z$204,MATCH(LARGE('⚡ COMMAND TRACKER'!$Y$5:$Y$204,10),'⚡ COMMAND TRACKER'!$Y$5:$Y$204,0)),"") | H13: =IFERROR(INDEX('⚡ COMMAND TRACKER'!$T$5:$T$204,MATCH(LARGE('⚡ COMMAND TRACKER'!$Y$5:$Y$204,10),'⚡ COMMAND TRACKER'!$Y$5:$Y$204,0)),"") -> 0 | I13: =IFERROR(INDEX('⚡ COMMAND TRACKER'!$U$5:$U$204,MATCH(LARGE('⚡ COMMAND TRACKER'!$Y$5:$Y$204,10),'⚡ COMMAND TRACKER'!$Y$5:$Y$204,0)),"") -> 0 | J13: =IFERROR(INDEX('⚡ COMMAND TRACKER'!$X$5:$X$204,MATCH(LARGE('⚡ COMMAND TRACKER'!$Y$5:$Y$204,10),'⚡ COMMAND TRACKER'!$Y$5:$Y$204,0)),"") -> 0 | K13: =IFERROR(INDEX('⚡ COMMAND TRACKER'!$AC$5:$AC$204,MATCH(LARGE('⚡ COMMAND TRACKER'!$Y$5:$Y$204,10),'⚡ COMMAND TRACKER'!$Y$5:$Y$204,0)),"") -> 0 | L13: =IFERROR(IF(K13="","",K13-TODAY()),"") | M13: =IFERROR(INDEX('⚡ COMMAND TRACKER'!$AE$5:$AE$204,MATCH(LARGE('⚡ COMMAND TRACKER'!$Y$5:$Y$204,10),'⚡ COMMAND TRACKER'!$Y$5:$Y$204,0)),"") -> 0
A14: =IFERROR(INDEX('⚡ COMMAND TRACKER'!$AA$5:$AA$204,MATCH(LARGE('⚡ COMMAND TRACKER'!$Y$5:$Y$204,11),'⚡ COMMAND TRACKER'!$Y$5:$Y$204,0)),"") -> ⏳ WORKING | B14: =IFERROR(INDEX('⚡ COMMAND TRACKER'!$A$5:$A$204,MATCH(LARGE('⚡ COMMAND TRACKER'!$Y$5:$Y$204,11),'⚡ COMMAND TRACKER'!$Y$5:$Y$204,0)),"") -> 0 | C14: =IFERROR(INDEX('⚡ COMMAND TRACKER'!$E$5:$E$204,MATCH(LARGE('⚡ COMMAND TRACKER'!$Y$5:$Y$204,11),'⚡ COMMAND TRACKER'!$Y$5:$Y$204,0)),"") -> 0 | D14: =IFERROR(INDEX('⚡ COMMAND TRACKER'!$B$5:$B$204,MATCH(LARGE('⚡ COMMAND TRACKER'!$Y$5:$Y$204,11),'⚡ COMMAND TRACKER'!$Y$5:$Y$204,0)),"") -> 0 | E14: =IFERROR(INDEX('⚡ COMMAND TRACKER'!$H$5:$H$204,MATCH(LARGE('⚡ COMMAND TRACKER'!$Y$5:$Y$204,11),'⚡ COMMAND TRACKER'!$Y$5:$Y$204,0)),"") -> 0 | F14: =IFERROR(LARGE('⚡ COMMAND TRACKER'!$Y$5:$Y$204,11),"") -> 0 | G14: =IFERROR(INDEX('⚡ COMMAND TRACKER'!$Z$5:$Z$204,MATCH(LARGE('⚡ COMMAND TRACKER'!$Y$5:$Y$204,11),'⚡ COMMAND TRACKER'!$Y$5:$Y$204,0)),"") | H14: =IFERROR(INDEX('⚡ COMMAND TRACKER'!$T$5:$T$204,MATCH(LARGE('⚡ COMMAND TRACKER'!$Y$5:$Y$204,11),'⚡ COMMAND TRACKER'!$Y$5:$Y$204,0)),"") -> 0 | I14: =IFERROR(INDEX('⚡ COMMAND TRACKER'!$U$5:$U$204,MATCH(LARGE('⚡ COMMAND TRACKER'!$Y$5:$Y$204,11),'⚡ COMMAND TRACKER'!$Y$5:$Y$204,0)),"") -> 0 | J14: =IFERROR(INDEX('⚡ COMMAND TRACKER'!$X$5:$X$204,MATCH(LARGE('⚡ COMMAND TRACKER'!$Y$5:$Y$204,11),'⚡ COMMAND TRACKER'!$Y$5:$Y$204,0)),"") -> 0 | K14: =IFERROR(INDEX('⚡ COMMAND TRACKER'!$AC$5:$AC$204,MATCH(LARGE('⚡ COMMAND TRACKER'!$Y$5:$Y$204,11),'⚡ COMMAND TRACKER'!$Y$5:$Y$204,0)),"") -> 0 | L14: =IFERROR(IF(K14="","",K14-TODAY()),"") | M14: =IFERROR(INDEX('⚡ COMMAND TRACKER'!$AE$5:$AE$204,MATCH(LARGE('⚡ COMMAND TRACKER'!$Y$5:$Y$204,11),'⚡ COMMAND TRACKER'!$Y$5:$Y$204,0)),"") -> 0
A15: =IFERROR(INDEX('⚡ COMMAND TRACKER'!$AA$5:$AA$204,MATCH(LARGE('⚡ COMMAND TRACKER'!$Y$5:$Y$204,12),'⚡ COMMAND TRACKER'!$Y$5:$Y$204,0)),"") -> ⏳ WORKING | B15: =IFERROR(INDEX('⚡ COMMAND TRACKER'!$A$5:$A$204,MATCH(LARGE('⚡ COMMAND TRACKER'!$Y$5:$Y$204,12),'⚡ COMMAND TRACKER'!$Y$5:$Y$204,0)),"") -> 0 | C15: =IFERROR(INDEX('⚡ COMMAND TRACKER'!$E$5:$E$204,MATCH(LARGE('⚡ COMMAND TRACKER'!$Y$5:$Y$204,12),'⚡ COMMAND TRACKER'!$Y$5:$Y$204,0)),"") -> 0 | D15: =IFERROR(INDEX('⚡ COMMAND TRACKER'!$B$5:$B$204,MATCH(LARGE('⚡ COMMAND TRACKER'!$Y$5:$Y$204,12),'⚡ COMMAND TRACKER'!$Y$5:$Y$204,0)),"") -> 0 | E15: =IFERROR(INDEX('⚡ COMMAND TRACKER'!$H$5:$H$204,MATCH(LARGE('⚡ COMMAND TRACKER'!$Y$5:$Y$204,12),'⚡ COMMAND TRACKER'!$Y$5:$Y$204,0)),"") -> 0 | F15: =IFERROR(LARGE('⚡ COMMAND TRACKER'!$Y$5:$Y$204,12),"") -> 0 | G15: =IFERROR(INDEX('⚡ COMMAND TRACKER'!$Z$5:$Z$204,MATCH(LARGE('⚡ COMMAND TRACKER'!$Y$5:$Y$204,12),'⚡ COMMAND TRACKER'!$Y$5:$Y$204,0)),"") | H15: =IFERROR(INDEX('⚡ COMMAND TRACKER'!$T$5:$T$204,MATCH(LARGE('⚡ COMMAND TRACKER'!$Y$5:$Y$204,12),'⚡ COMMAND TRACKER'!$Y$5:$Y$204,0)),"") -> 0 | I15: =IFERROR(INDEX('⚡ COMMAND TRACKER'!$U$5:$U$204,MATCH(LARGE('⚡ COMMAND TRACKER'!$Y$5:$Y$204,12),'⚡ COMMAND TRACKER'!$Y$5:$Y$204,0)),"") -> 0 | J15: =IFERROR(INDEX('⚡ COMMAND TRACKER'!$X$5:$X$204,MATCH(LARGE('⚡ COMMAND TRACKER'!$Y$5:$Y$204,12),'⚡ COMMAND TRACKER'!$Y$5:$Y$204,0)),"") -> 0 | K15: =IFERROR(INDEX('⚡ COMMAND TRACKER'!$AC$5:$AC$204,MATCH(LARGE('⚡ COMMAND TRACKER'!$Y$5:$Y$204,12),'⚡ COMMAND TRACKER'!$Y$5:$Y$204,0)),"") -> 0 | L15: =IFERROR(IF(K15="","",K15-TODAY()),"") | M15: =IFERROR(INDEX('⚡ COMMAND TRACKER'!$AE$5:$AE$204,MATCH(LARGE('⚡ COMMAND TRACKER'!$Y$5:$Y$204,12),'⚡ COMMAND TRACKER'!$Y$5:$Y$204,0)),"") -> 0
A16: =IFERROR(INDEX('⚡ COMMAND TRACKER'!$AA$5:$AA$204,MATCH(LARGE('⚡ COMMAND TRACKER'!$Y$5:$Y$204,13),'⚡ COMMAND TRACKER'!$Y$5:$Y$204,0)),"") -> ⏳ WORKING | B16: =IFERROR(INDEX('⚡ COMMAND TRACKER'!$A$5:$A$204,MATCH(LARGE('⚡ COMMAND TRACKER'!$Y$5:$Y$204,13),'⚡ COMMAND TRACKER'!$Y$5:$Y$204,0)),"") -> 0 | C16: =IFERROR(INDEX('⚡ COMMAND TRACKER'!$E$5:$E$204,MATCH(LARGE('⚡ COMMAND TRACKER'!$Y$5:$Y$204,13),'⚡ COMMAND TRACKER'!$Y$5:$Y$204,0)),"") -> 0 | D16: =IFERROR(INDEX('⚡ COMMAND TRACKER'!$B$5:$B$204,MATCH(LARGE('⚡ COMMAND TRACKER'!$Y$5:$Y$204,13),'⚡ COMMAND TRACKER'!$Y$5:$Y$204,0)),"") -> 0 | E16: =IFERROR(INDEX('⚡ COMMAND TRACKER'!$H$5:$H$204,MATCH(LARGE('⚡ COMMAND TRACKER'!$Y$5:$Y$204,13),'⚡ COMMAND TRACKER'!$Y$5:$Y$204,0)),"") -> 0 | F16: =IFERROR(LARGE('⚡ COMMAND TRACKER'!$Y$5:$Y$204,13),"") -> 0 | G16: =IFERROR(INDEX('⚡ COMMAND TRACKER'!$Z$5:$Z$204,MATCH(LARGE('⚡ COMMAND TRACKER'!$Y$5:$Y$204,13),'⚡ COMMAND TRACKER'!$Y$5:$Y$204,0)),"") | H16: =IFERROR(INDEX('⚡ COMMAND TRACKER'!$T$5:$T$204,MATCH(LARGE('⚡ COMMAND TRACKER'!$Y$5:$Y$204,13),'⚡ COMMAND TRACKER'!$Y$5:$Y$204,0)),"") -> 0 | I16: =IFERROR(INDEX('⚡ COMMAND TRACKER'!$U$5:$U$204,MATCH(LARGE('⚡ COMMAND TRACKER'!$Y$5:$Y$204,13),'⚡ COMMAND TRACKER'!$Y$5:$Y$204,0)),"") -> 0 | J16: =IFERROR(INDEX('⚡ COMMAND TRACKER'!$X$5:$X$204,MATCH(LARGE('⚡ COMMAND TRACKER'!$Y$5:$Y$204,13),'⚡ COMMAND TRACKER'!$Y$5:$Y$204,0)),"") -> 0 | K16: =IFERROR(INDEX('⚡ COMMAND TRACKER'!$AC$5:$AC$204,MATCH(LARGE('⚡ COMMAND TRACKER'!$Y$5:$Y$204,13),'⚡ COMMAND TRACKER'!$Y$5:$Y$204,0)),"") -> 0 | L16: =IFERROR(IF(K16="","",K16-TODAY()),"") | M16: =IFERROR(INDEX('⚡ COMMAND TRACKER'!$AE$5:$AE$204,MATCH(LARGE('⚡ COMMAND TRACKER'!$Y$5:$Y$204,13),'⚡ COMMAND TRACKER'!$Y$5:$Y$204,0)),"") -> 0
A17: =IFERROR(INDEX('⚡ COMMAND TRACKER'!$AA$5:$AA$204,MATCH(LARGE('⚡ COMMAND TRACKER'!$Y$5:$Y$204,14),'⚡ COMMAND TRACKER'!$Y$5:$Y$204,0)),"") -> ⏳ WORKING | B17: =IFERROR(INDEX('⚡ COMMAND TRACKER'!$A$5:$A$204,MATCH(LARGE('⚡ COMMAND TRACKER'!$Y$5:$Y$204,14),'⚡ COMMAND TRACKER'!$Y$5:$Y$204,0)),"") -> 0 | C17: =IFERROR(INDEX('⚡ COMMAND TRACKER'!$E$5:$E$204,MATCH(LARGE('⚡ COMMAND TRACKER'!$Y$5:$Y$204,14),'⚡ COMMAND TRACKER'!$Y$5:$Y$204,0)),"") -> 0 | D17: =IFERROR(INDEX('⚡ COMMAND TRACKER'!$B$5:$B$204,MATCH(LARGE('⚡ COMMAND TRACKER'!$Y$5:$Y$204,14),'⚡ COMMAND TRACKER'!$Y$5:$Y$204,0)),"") -> 0 | E17: =IFERROR(INDEX('⚡ COMMAND TRACKER'!$H$5:$H$204,MATCH(LARGE('⚡ COMMAND TRACKER'!$Y$5:$Y$204,14),'⚡ COMMAND TRACKER'!$Y$5:$Y$204,0)),"") -> 0 | F17: =IFERROR(LARGE('⚡ COMMAND TRACKER'!$Y$5:$Y$204,14),"") -> 0 | G17: =IFERROR(INDEX('⚡ COMMAND TRACKER'!$Z$5:$Z$204,MATCH(LARGE('⚡ COMMAND TRACKER'!$Y$5:$Y$204,14),'⚡ COMMAND TRACKER'!$Y$5:$Y$204,0)),"") | H17: =IFERROR(INDEX('⚡ COMMAND TRACKER'!$T$5:$T$204,MATCH(LARGE('⚡ COMMAND TRACKER'!$Y$5:$Y$204,14),'⚡ COMMAND TRACKER'!$Y$5:$Y$204,0)),"") -> 0 | I17: =IFERROR(INDEX('⚡ COMMAND TRACKER'!$U$5:$U$204,MATCH(LARGE('⚡ COMMAND TRACKER'!$Y$5:$Y$204,14),'⚡ COMMAND TRACKER'!$Y$5:$Y$204,0)),"") -> 0 | J17: =IFERROR(INDEX('⚡ COMMAND TRACKER'!$X$5:$X$204,MATCH(LARGE('⚡ COMMAND TRACKER'!$Y$5:$Y$204,14),'⚡ COMMAND TRACKER'!$Y$5:$Y$204,0)),"") -> 0 | K17: =IFERROR(INDEX('⚡ COMMAND TRACKER'!$AC$5:$AC$204,MATCH(LARGE('⚡ COMMAND TRACKER'!$Y$5:$Y$204,14),'⚡ COMMAND TRACKER'!$Y$5:$Y$204,0)),"") -> 0 | L17: =IFERROR(IF(K17="","",K17-TODAY()),"") | M17: =IFERROR(INDEX('⚡ COMMAND TRACKER'!$AE$5:$AE$204,MATCH(LARGE('⚡ COMMAND TRACKER'!$Y$5:$Y$204,14),'⚡ COMMAND TRACKER'!$Y$5:$Y$204,0)),"") -> 0
A18: =IFERROR(INDEX('⚡ COMMAND TRACKER'!$AA$5:$AA$204,MATCH(LARGE('⚡ COMMAND TRACKER'!$Y$5:$Y$204,15),'⚡ COMMAND TRACKER'!$Y$5:$Y$204,0)),"") -> ⏳ WORKING | B18: =IFERROR(INDEX('⚡ COMMAND TRACKER'!$A$5:$A$204,MATCH(LARGE('⚡ COMMAND TRACKER'!$Y$5:$Y$204,15),'⚡ COMMAND TRACKER'!$Y$5:$Y$204,0)),"") -> 0 | C18: =IFERROR(INDEX('⚡ COMMAND TRACKER'!$E$5:$E$204,MATCH(LARGE('⚡ COMMAND TRACKER'!$Y$5:$Y$204,15),'⚡ COMMAND TRACKER'!$Y$5:$Y$204,0)),"") -> 0 | D18: =IFERROR(INDEX('⚡ COMMAND TRACKER'!$B$5:$B$204,MATCH(LARGE('⚡ COMMAND TRACKER'!$Y$5:$Y$204,15),'⚡ COMMAND TRACKER'!$Y$5:$Y$204,0)),"") -> 0 | E18: =IFERROR(INDEX('⚡ COMMAND TRACKER'!$H$5:$H$204,MATCH(LARGE('⚡ COMMAND TRACKER'!$Y$5:$Y$204,15),'⚡ COMMAND TRACKER'!$Y$5:$Y$204,0)),"") -> 0 | F18: =IFERROR(LARGE('⚡ COMMAND TRACKER'!$Y$5:$Y$204,15),"") -> 0 | G18: =IFERROR(INDEX('⚡ COMMAND TRACKER'!$Z$5:$Z$204,MATCH(LARGE('⚡ COMMAND TRACKER'!$Y$5:$Y$204,15),'⚡ COMMAND TRACKER'!$Y$5:$Y$204,0)),"") | H18: =IFERROR(INDEX('⚡ COMMAND TRACKER'!$T$5:$T$204,MATCH(LARGE('⚡ COMMAND TRACKER'!$Y$5:$Y$204,15),'⚡ COMMAND TRACKER'!$Y$5:$Y$204,0)),"") -> 0 | I18: =IFERROR(INDEX('⚡ COMMAND TRACKER'!$U$5:$U$204,MATCH(LARGE('⚡ COMMAND TRACKER'!$Y$5:$Y$204,15),'⚡ COMMAND TRACKER'!$Y$5:$Y$204,0)),"") -> 0 | J18: =IFERROR(INDEX('⚡ COMMAND TRACKER'!$X$5:$X$204,MATCH(LARGE('⚡ COMMAND TRACKER'!$Y$5:$Y$204,15),'⚡ COMMAND TRACKER'!$Y$5:$Y$204,0)),"") -> 0 | K18: =IFERROR(INDEX('⚡ COMMAND TRACKER'!$AC$5:$AC$204,MATCH(LARGE('⚡ COMMAND TRACKER'!$Y$5:$Y$204,15),'⚡ COMMAND TRACKER'!$Y$5:$Y$204,0)),"") -> 0 | L18: =IFERROR(IF(K18="","",K18-TODAY()),"") | M18: =IFERROR(INDEX('⚡ COMMAND TRACKER'!$AE$5:$AE$204,MATCH(LARGE('⚡ COMMAND TRACKER'!$Y$5:$Y$204,15),'⚡ COMMAND TRACKER'!$Y$5:$Y$204,0)),"") -> 0
A19: =IFERROR(INDEX('⚡ COMMAND TRACKER'!$AA$5:$AA$204,MATCH(LARGE('⚡ COMMAND TRACKER'!$Y$5:$Y$204,16),'⚡ COMMAND TRACKER'!$Y$5:$Y$204,0)),"") -> ⏳ WORKING | B19: =IFERROR(INDEX('⚡ COMMAND TRACKER'!$A$5:$A$204,MATCH(LARGE('⚡ COMMAND TRACKER'!$Y$5:$Y$204,16),'⚡ COMMAND TRACKER'!$Y$5:$Y$204,0)),"") -> 0 | C19: =IFERROR(INDEX('⚡ COMMAND TRACKER'!$E$5:$E$204,MATCH(LARGE('⚡ COMMAND TRACKER'!$Y$5:$Y$204,16),'⚡ COMMAND TRACKER'!$Y$5:$Y$204,0)),"") -> 0 | D19: =IFERROR(INDEX('⚡ COMMAND TRACKER'!$B$5:$B$204,MATCH(LARGE('⚡ COMMAND TRACKER'!$Y$5:$Y$204,16),'⚡ COMMAND TRACKER'!$Y$5:$Y$204,0)),"") -> 0 | E19: =IFERROR(INDEX('⚡ COMMAND TRACKER'!$H$5:$H$204,MATCH(LARGE('⚡ COMMAND TRACKER'!$Y$5:$Y$204,16),'⚡ COMMAND TRACKER'!$Y$5:$Y$204,0)),"") -> 0 | F19: =IFERROR(LARGE('⚡ COMMAND TRACKER'!$Y$5:$Y$204,16),"") -> 0 | G19: =IFERROR(INDEX('⚡ COMMAND TRACKER'!$Z$5:$Z$204,MATCH(LARGE('⚡ COMMAND TRACKER'!$Y$5:$Y$204,16),'⚡ COMMAND TRACKER'!$Y$5:$Y$204,0)),"") | H19: =IFERROR(INDEX('⚡ COMMAND TRACKER'!$T$5:$T$204,MATCH(LARGE('⚡ COMMAND TRACKER'!$Y$5:$Y$204,16),'⚡ COMMAND TRACKER'!$Y$5:$Y$204,0)),"") -> 0 | I19: =IFERROR(INDEX('⚡ COMMAND TRACKER'!$U$5:$U$204,MATCH(LARGE('⚡ COMMAND TRACKER'!$Y$5:$Y$204,16),'⚡ COMMAND TRACKER'!$Y$5:$Y$204,0)),"") -> 0 | J19: =IFERROR(INDEX('⚡ COMMAND TRACKER'!$X$5:$X$204,MATCH(LARGE('⚡ COMMAND TRACKER'!$Y$5:$Y$204,16),'⚡ COMMAND TRACKER'!$Y$5:$Y$204,0)),"") -> 0 | K19: =IFERROR(INDEX('⚡ COMMAND TRACKER'!$AC$5:$AC$204,MATCH(LARGE('⚡ COMMAND TRACKER'!$Y$5:$Y$204,16),'⚡ COMMAND TRACKER'!$Y$5:$Y$204,0)),"") -> 0 | L19: =IFERROR(IF(K19="","",K19-TODAY()),"") | M19: =IFERROR(INDEX('⚡ COMMAND TRACKER'!$AE$5:$AE$204,MATCH(LARGE('⚡ COMMAND TRACKER'!$Y$5:$Y$204,16),'⚡ COMMAND TRACKER'!$Y$5:$Y$204,0)),"") -> 0
A20: =IFERROR(INDEX('⚡ COMMAND TRACKER'!$AA$5:$AA$204,MATCH(LARGE('⚡ COMMAND TRACKER'!$Y$5:$Y$204,17),'⚡ COMMAND TRACKER'!$Y$5:$Y$204,0)),"") -> ⏳ WORKING | B20: =IFERROR(INDEX('⚡ COMMAND TRACKER'!$A$5:$A$204,MATCH(LARGE('⚡ COMMAND TRACKER'!$Y$5:$Y$204,17),'⚡ COMMAND TRACKER'!$Y$5:$Y$204,0)),"") -> 0 | C20: =IFERROR(INDEX('⚡ COMMAND TRACKER'!$E$5:$E$204,MATCH(LARGE('⚡ COMMAND TRACKER'!$Y$5:$Y$204,17),'⚡ COMMAND TRACKER'!$Y$5:$Y$204,0)),"") -> 0 | D20: =IFERROR(INDEX('⚡ COMMAND TRACKER'!$B$5:$B$204,MATCH(LARGE('⚡ COMMAND TRACKER'!$Y$5:$Y$204,17),'⚡ COMMAND TRACKER'!$Y$5:$Y$204,0)),"") -> 0 | E20: =IFERROR(INDEX('⚡ COMMAND TRACKER'!$H$5:$H$204,MATCH(LARGE('⚡ COMMAND TRACKER'!$Y$5:$Y$204,17),'⚡ COMMAND TRACKER'!$Y$5:$Y$204,0)),"") -> 0 | F20: =IFERROR(LARGE('⚡ COMMAND TRACKER'!$Y$5:$Y$204,17),"") -> 0 | G20: =IFERROR(INDEX('⚡ COMMAND TRACKER'!$Z$5:$Z$204,MATCH(LARGE('⚡ COMMAND TRACKER'!$Y$5:$Y$204,17),'⚡ COMMAND TRACKER'!$Y$5:$Y$204,0)),"") | H20: =IFERROR(INDEX('⚡ COMMAND TRACKER'!$T$5:$T$204,MATCH(LARGE('⚡ COMMAND TRACKER'!$Y$5:$Y$204,17),'⚡ COMMAND TRACKER'!$Y$5:$Y$204,0)),"") -> 0 | I20: =IFERROR(INDEX('⚡ COMMAND TRACKER'!$U$5:$U$204,MATCH(LARGE('⚡ COMMAND TRACKER'!$Y$5:$Y$204,17),'⚡ COMMAND TRACKER'!$Y$5:$Y$204,0)),"") -> 0 | J20: =IFERROR(INDEX('⚡ COMMAND TRACKER'!$X$5:$X$204,MATCH(LARGE('⚡ COMMAND TRACKER'!$Y$5:$Y$204,17),'⚡ COMMAND TRACKER'!$Y$5:$Y$204,0)),"") -> 0 | K20: =IFERROR(INDEX('⚡ COMMAND TRACKER'!$AC$5:$AC$204,MATCH(LARGE('⚡ COMMAND TRACKER'!$Y$5:$Y$204,17),'⚡ COMMAND TRACKER'!$Y$5:$Y$204,0)),"") -> 0 | L20: =IFERROR(IF(K20="","",K20-TODAY()),"") | M20: =IFERROR(INDEX('⚡ COMMAND TRACKER'!$AE$5:$AE$204,MATCH(LARGE('⚡ COMMAND TRACKER'!$Y$5:$Y$204,17),'⚡ COMMAND TRACKER'!$Y$5:$Y$204,0)),"") -> 0
A21: =IFERROR(INDEX('⚡ COMMAND TRACKER'!$AA$5:$AA$204,MATCH(LARGE('⚡ COMMAND TRACKER'!$Y$5:$Y$204,18),'⚡ COMMAND TRACKER'!$Y$5:$Y$204,0)),"") -> ⏳ WORKING | B21: =IFERROR(INDEX('⚡ COMMAND TRACKER'!$A$5:$A$204,MATCH(LARGE('⚡ COMMAND TRACKER'!$Y$5:$Y$204,18),'⚡ COMMAND TRACKER'!$Y$5:$Y$204,0)),"") -> 0 | C21: =IFERROR(INDEX('⚡ COMMAND TRACKER'!$E$5:$E$204,MATCH(LARGE('⚡ COMMAND TRACKER'!$Y$5:$Y$204,18),'⚡ COMMAND TRACKER'!$Y$5:$Y$204,0)),"") -> 0 | D21: =IFERROR(INDEX('⚡ COMMAND TRACKER'!$B$5:$B$204,MATCH(LARGE('⚡ COMMAND TRACKER'!$Y$5:$Y$204,18),'⚡ COMMAND TRACKER'!$Y$5:$Y$204,0)),"") -> 0 | E21: =IFERROR(INDEX('⚡ COMMAND TRACKER'!$H$5:$H$204,MATCH(LARGE('⚡ COMMAND TRACKER'!$Y$5:$Y$204,18),'⚡ COMMAND TRACKER'!$Y$5:$Y$204,0)),"") -> 0 | F21: =IFERROR(LARGE('⚡ COMMAND TRACKER'!$Y$5:$Y$204,18),"") -> 0 | G21: =IFERROR(INDEX('⚡ COMMAND TRACKER'!$Z$5:$Z$204,MATCH(LARGE('⚡ COMMAND TRACKER'!$Y$5:$Y$204,18),'⚡ COMMAND TRACKER'!$Y$5:$Y$204,0)),"") | H21: =IFERROR(INDEX('⚡ COMMAND TRACKER'!$T$5:$T$204,MATCH(LARGE('⚡ COMMAND TRACKER'!$Y$5:$Y$204,18),'⚡ COMMAND TRACKER'!$Y$5:$Y$204,0)),"") -> 0 | I21: =IFERROR(INDEX('⚡ COMMAND TRACKER'!$U$5:$U$204,MATCH(LARGE('⚡ COMMAND TRACKER'!$Y$5:$Y$204,18),'⚡ COMMAND TRACKER'!$Y$5:$Y$204,0)),"") -> 0 | J21: =IFERROR(INDEX('⚡ COMMAND TRACKER'!$X$5:$X$204,MATCH(LARGE('⚡ COMMAND TRACKER'!$Y$5:$Y$204,18),'⚡ COMMAND TRACKER'!$Y$5:$Y$204,0)),"") -> 0 | K21: =IFERROR(INDEX('⚡ COMMAND TRACKER'!$AC$5:$AC$204,MATCH(LARGE('⚡ COMMAND TRACKER'!$Y$5:$Y$204,18),'⚡ COMMAND TRACKER'!$Y$5:$Y$204,0)),"") -> 0 | L21: =IFERROR(IF(K21="","",K21-TODAY()),"") | M21: =IFERROR(INDEX('⚡ COMMAND TRACKER'!$AE$5:$AE$204,MATCH(LARGE('⚡ COMMAND TRACKER'!$Y$5:$Y$204,18),'⚡ COMMAND TRACKER'!$Y$5:$Y$204,0)),"") -> 0
A22: =IFERROR(INDEX('⚡ COMMAND TRACKER'!$AA$5:$AA$204,MATCH(LARGE('⚡ COMMAND TRACKER'!$Y$5:$Y$204,19),'⚡ COMMAND TRACKER'!$Y$5:$Y$204,0)),"") -> ⏳ WORKING | B22: =IFERROR(INDEX('⚡ COMMAND TRACKER'!$A$5:$A$204,MATCH(LARGE('⚡ COMMAND TRACKER'!$Y$5:$Y$204,19),'⚡ COMMAND TRACKER'!$Y$5:$Y$204,0)),"") -> 0 | C22: =IFERROR(INDEX('⚡ COMMAND TRACKER'!$E$5:$E$204,MATCH(LARGE('⚡ COMMAND TRACKER'!$Y$5:$Y$204,19),'⚡ COMMAND TRACKER'!$Y$5:$Y$204,0)),"") -> 0 | D22: =IFERROR(INDEX('⚡ COMMAND TRACKER'!$B$5:$B$204,MATCH(LARGE('⚡ COMMAND TRACKER'!$Y$5:$Y$204,19),'⚡ COMMAND TRACKER'!$Y$5:$Y$204,0)),"") -> 0 | E22: =IFERROR(INDEX('⚡ COMMAND TRACKER'!$H$5:$H$204,MATCH(LARGE('⚡ COMMAND TRACKER'!$Y$5:$Y$204,19),'⚡ COMMAND TRACKER'!$Y$5:$Y$204,0)),"") -> 0 | F22: =IFERROR(LARGE('⚡ COMMAND TRACKER'!$Y$5:$Y$204,19),"") -> 0 | G22: =IFERROR(INDEX('⚡ COMMAND TRACKER'!$Z$5:$Z$204,MATCH(LARGE('⚡ COMMAND TRACKER'!$Y$5:$Y$204,19),'⚡ COMMAND TRACKER'!$Y$5:$Y$204,0)),"") | H22: =IFERROR(INDEX('⚡ COMMAND TRACKER'!$T$5:$T$204,MATCH(LARGE('⚡ COMMAND TRACKER'!$Y$5:$Y$204,19),'⚡ COMMAND TRACKER'!$Y$5:$Y$204,0)),"") -> 0 | I22: =IFERROR(INDEX('⚡ COMMAND TRACKER'!$U$5:$U$204,MATCH(LARGE('⚡ COMMAND TRACKER'!$Y$5:$Y$204,19),'⚡ COMMAND TRACKER'!$Y$5:$Y$204,0)),"") -> 0 | J22: =IFERROR(INDEX('⚡ COMMAND TRACKER'!$X$5:$X$204,MATCH(LARGE('⚡ COMMAND TRACKER'!$Y$5:$Y$204,19),'⚡ COMMAND TRACKER'!$Y$5:$Y$204,0)),"") -> 0 | K22: =IFERROR(INDEX('⚡ COMMAND TRACKER'!$AC$5:$AC$204,MATCH(LARGE('⚡ COMMAND TRACKER'!$Y$5:$Y$204,19),'⚡ COMMAND TRACKER'!$Y$5:$Y$204,0)),"") -> 0 | L22: =IFERROR(IF(K22="","",K22-TODAY()),"") | M22: =IFERROR(INDEX('⚡ COMMAND TRACKER'!$AE$5:$AE$204,MATCH(LARGE('⚡ COMMAND TRACKER'!$Y$5:$Y$204,19),'⚡ COMMAND TRACKER'!$Y$5:$Y$204,0)),"") -> 0
A23: =IFERROR(INDEX('⚡ COMMAND TRACKER'!$AA$5:$AA$204,MATCH(LARGE('⚡ COMMAND TRACKER'!$Y$5:$Y$204,20),'⚡ COMMAND TRACKER'!$Y$5:$Y$204,0)),"") -> ⏳ WORKING | B23: =IFERROR(INDEX('⚡ COMMAND TRACKER'!$A$5:$A$204,MATCH(LARGE('⚡ COMMAND TRACKER'!$Y$5:$Y$204,20),'⚡ COMMAND TRACKER'!$Y$5:$Y$204,0)),"") -> 0 | C23: =IFERROR(INDEX('⚡ COMMAND TRACKER'!$E$5:$E$204,MATCH(LARGE('⚡ COMMAND TRACKER'!$Y$5:$Y$204,20),'⚡ COMMAND TRACKER'!$Y$5:$Y$204,0)),"") -> 0 | D23: =IFERROR(INDEX('⚡ COMMAND TRACKER'!$B$5:$B$204,MATCH(LARGE('⚡ COMMAND TRACKER'!$Y$5:$Y$204,20),'⚡ COMMAND TRACKER'!$Y$5:$Y$204,0)),"") -> 0 | E23: =IFERROR(INDEX('⚡ COMMAND TRACKER'!$H$5:$H$204,MATCH(LARGE('⚡ COMMAND TRACKER'!$Y$5:$Y$204,20),'⚡ COMMAND TRACKER'!$Y$5:$Y$204,0)),"") -> 0 | F23: =IFERROR(LARGE('⚡ COMMAND TRACKER'!$Y$5:$Y$204,20),"") -> 0 | G23: =IFERROR(INDEX('⚡ COMMAND TRACKER'!$Z$5:$Z$204,MATCH(LARGE('⚡ COMMAND TRACKER'!$Y$5:$Y$204,20),'⚡ COMMAND TRACKER'!$Y$5:$Y$204,0)),"") | H23: =IFERROR(INDEX('⚡ COMMAND TRACKER'!$T$5:$T$204,MATCH(LARGE('⚡ COMMAND TRACKER'!$Y$5:$Y$204,20),'⚡ COMMAND TRACKER'!$Y$5:$Y$204,0)),"") -> 0 | I23: =IFERROR(INDEX('⚡ COMMAND TRACKER'!$U$5:$U$204,MATCH(LARGE('⚡ COMMAND TRACKER'!$Y$5:$Y$204,20),'⚡ COMMAND TRACKER'!$Y$5:$Y$204,0)),"") -> 0 | J23: =IFERROR(INDEX('⚡ COMMAND TRACKER'!$X$5:$X$204,MATCH(LARGE('⚡ COMMAND TRACKER'!$Y$5:$Y$204,20),'⚡ COMMAND TRACKER'!$Y$5:$Y$204,0)),"") -> 0 | K23: =IFERROR(INDEX('⚡ COMMAND TRACKER'!$AC$5:$AC$204,MATCH(LARGE('⚡ COMMAND TRACKER'!$Y$5:$Y$204,20),'⚡ COMMAND TRACKER'!$Y$5:$Y$204,0)),"") -> 0 | L23: =IFERROR(IF(K23="","",K23-TODAY()),"") | M23: =IFERROR(INDEX('⚡ COMMAND TRACKER'!$AE$5:$AE$204,MATCH(LARGE('⚡ COMMAND TRACKER'!$Y$5:$Y$204,20),'⚡ COMMAND TRACKER'!$Y$5:$Y$204,0)),"") -> 0
A24: =IFERROR(INDEX('⚡ COMMAND TRACKER'!$AA$5:$AA$204,MATCH(LARGE('⚡ COMMAND TRACKER'!$Y$5:$Y$204,21),'⚡ COMMAND TRACKER'!$Y$5:$Y$204,0)),"") -> ⏳ WORKING | B24: =IFERROR(INDEX('⚡ COMMAND TRACKER'!$A$5:$A$204,MATCH(LARGE('⚡ COMMAND TRACKER'!$Y$5:$Y$204,21),'⚡ COMMAND TRACKER'!$Y$5:$Y$204,0)),"") -> 0 | C24: =IFERROR(INDEX('⚡ COMMAND TRACKER'!$E$5:$E$204,MATCH(LARGE('⚡ COMMAND TRACKER'!$Y$5:$Y$204,21),'⚡ COMMAND TRACKER'!$Y$5:$Y$204,0)),"") -> 0 | D24: =IFERROR(INDEX('⚡ COMMAND TRACKER'!$B$5:$B$204,MATCH(LARGE('⚡ COMMAND TRACKER'!$Y$5:$Y$204,21),'⚡ COMMAND TRACKER'!$Y$5:$Y$204,0)),"") -> 0 | E24: =IFERROR(INDEX('⚡ COMMAND TRACKER'!$H$5:$H$204,MATCH(LARGE('⚡ COMMAND TRACKER'!$Y$5:$Y$204,21),'⚡ COMMAND TRACKER'!$Y$5:$Y$204,0)),"") -> 0 | F24: =IFERROR(LARGE('⚡ COMMAND TRACKER'!$Y$5:$Y$204,21),"") -> 0 | G24: =IFERROR(INDEX('⚡ COMMAND TRACKER'!$Z$5:$Z$204,MATCH(LARGE('⚡ COMMAND TRACKER'!$Y$5:$Y$204,21),'⚡ COMMAND TRACKER'!$Y$5:$Y$204,0)),"") | H24: =IFERROR(INDEX('⚡ COMMAND TRACKER'!$T$5:$T$204,MATCH(LARGE('⚡ COMMAND TRACKER'!$Y$5:$Y$204,21),'⚡ COMMAND TRACKER'!$Y$5:$Y$204,0)),"") -> 0 | I24: =IFERROR(INDEX('⚡ COMMAND TRACKER'!$U$5:$U$204,MATCH(LARGE('⚡ COMMAND TRACKER'!$Y$5:$Y$204,21),'⚡ COMMAND TRACKER'!$Y$5:$Y$204,0)),"") -> 0 | J24: =IFERROR(INDEX('⚡ COMMAND TRACKER'!$X$5:$X$204,MATCH(LARGE('⚡ COMMAND TRACKER'!$Y$5:$Y$204,21),'⚡ COMMAND TRACKER'!$Y$5:$Y$204,0)),"") -> 0 | K24: =IFERROR(INDEX('⚡ COMMAND TRACKER'!$AC$5:$AC$204,MATCH(LARGE('⚡ COMMAND TRACKER'!$Y$5:$Y$204,21),'⚡ COMMAND TRACKER'!$Y$5:$Y$204,0)),"") -> 0 | L24: =IFERROR(IF(K24="","",K24-TODAY()),"") | M24: =IFERROR(INDEX('⚡ COMMAND TRACKER'!$AE$5:$AE$204,MATCH(LARGE('⚡ COMMAND TRACKER'!$Y$5:$Y$204,21),'⚡ COMMAND TRACKER'!$Y$5:$Y$204,0)),"") -> 0
A25: =IFERROR(INDEX('⚡ COMMAND TRACKER'!$AA$5:$AA$204,MATCH(LARGE('⚡ COMMAND TRACKER'!$Y$5:$Y$204,22),'⚡ COMMAND TRACKER'!$Y$5:$Y$204,0)),"") -> ⏳ WORKING | B25: =IFERROR(INDEX('⚡ COMMAND TRACKER'!$A$5:$A$204,MATCH(LARGE('⚡ COMMAND TRACKER'!$Y$5:$Y$204,22),'⚡ COMMAND TRACKER'!$Y$5:$Y$204,0)),"") -> 0 | C25: =IFERROR(INDEX('⚡ COMMAND TRACKER'!$E$5:$E$204,MATCH(LARGE('⚡ COMMAND TRACKER'!$Y$5:$Y$204,22),'⚡ COMMAND TRACKER'!$Y$5:$Y$204,0)),"") -> 0 | D25: =IFERROR(INDEX('⚡ COMMAND TRACKER'!$B$5:$B$204,MATCH(LARGE('⚡ COMMAND TRACKER'!$Y$5:$Y$204,22),'⚡ COMMAND TRACKER'!$Y$5:$Y$204,0)),"") -> 0 | E25: =IFERROR(INDEX('⚡ COMMAND TRACKER'!$H$5:$H$204,MATCH(LARGE('⚡ COMMAND TRACKER'!$Y$5:$Y$204,22),'⚡ COMMAND TRACKER'!$Y$5:$Y$204,0)),"") -> 0 | F25: =IFERROR(LARGE('⚡ COMMAND TRACKER'!$Y$5:$Y$204,22),"") -> 0 | G25: =IFERROR(INDEX('⚡ COMMAND TRACKER'!$Z$5:$Z$204,MATCH(LARGE('⚡ COMMAND TRACKER'!$Y$5:$Y$204,22),'⚡ COMMAND TRACKER'!$Y$5:$Y$204,0)),"") | H25: =IFERROR(INDEX('⚡ COMMAND TRACKER'!$T$5:$T$204,MATCH(LARGE('⚡ COMMAND TRACKER'!$Y$5:$Y$204,22),'⚡ COMMAND TRACKER'!$Y$5:$Y$204,0)),"") -> 0 | I25: =IFERROR(INDEX('⚡ COMMAND TRACKER'!$U$5:$U$204,MATCH(LARGE('⚡ COMMAND TRACKER'!$Y$5:$Y$204,22),'⚡ COMMAND TRACKER'!$Y$5:$Y$204,0)),"") -> 0 | J25: =IFERROR(INDEX('⚡ COMMAND TRACKER'!$X$5:$X$204,MATCH(LARGE('⚡ COMMAND TRACKER'!$Y$5:$Y$204,22),'⚡ COMMAND TRACKER'!$Y$5:$Y$204,0)),"") -> 0 | K25: =IFERROR(INDEX('⚡ COMMAND TRACKER'!$AC$5:$AC$204,MATCH(LARGE('⚡ COMMAND TRACKER'!$Y$5:$Y$204,22),'⚡ COMMAND TRACKER'!$Y$5:$Y$204,0)),"") -> 0 | L25: =IFERROR(IF(K25="","",K25-TODAY()),"") | M25: =IFERROR(INDEX('⚡ COMMAND TRACKER'!$AE$5:$AE$204,MATCH(LARGE('⚡ COMMAND TRACKER'!$Y$5:$Y$204,22),'⚡ COMMAND TRACKER'!$Y$5:$Y$204,0)),"") -> 0
A26: =IFERROR(INDEX('⚡ COMMAND TRACKER'!$AA$5:$AA$204,MATCH(LARGE('⚡ COMMAND TRACKER'!$Y$5:$Y$204,23),'⚡ COMMAND TRACKER'!$Y$5:$Y$204,0)),"") -> ⏳ WORKING | B26: =IFERROR(INDEX('⚡ COMMAND TRACKER'!$A$5:$A$204,MATCH(LARGE('⚡ COMMAND TRACKER'!$Y$5:$Y$204,23),'⚡ COMMAND TRACKER'!$Y$5:$Y$204,0)),"") -> 0 | C26: =IFERROR(INDEX('⚡ COMMAND TRACKER'!$E$5:$E$204,MATCH(LARGE('⚡ COMMAND TRACKER'!$Y$5:$Y$204,23),'⚡ COMMAND TRACKER'!$Y$5:$Y$204,0)),"") -> 0 | D26: =IFERROR(INDEX('⚡ COMMAND TRACKER'!$B$5:$B$204,MATCH(LARGE('⚡ COMMAND TRACKER'!$Y$5:$Y$204,23),'⚡ COMMAND TRACKER'!$Y$5:$Y$204,0)),"") -> 0 | E26: =IFERROR(INDEX('⚡ COMMAND TRACKER'!$H$5:$H$204,MATCH(LARGE('⚡ COMMAND TRACKER'!$Y$5:$Y$204,23),'⚡ COMMAND TRACKER'!$Y$5:$Y$204,0)),"") -> 0 | F26: =IFERROR(LARGE('⚡ COMMAND TRACKER'!$Y$5:$Y$204,23),"") -> 0 | G26: =IFERROR(INDEX('⚡ COMMAND TRACKER'!$Z$5:$Z$204,MATCH(LARGE('⚡ COMMAND TRACKER'!$Y$5:$Y$204,23),'⚡ COMMAND TRACKER'!$Y$5:$Y$204,0)),"") | H26: =IFERROR(INDEX('⚡ COMMAND TRACKER'!$T$5:$T$204,MATCH(LARGE('⚡ COMMAND TRACKER'!$Y$5:$Y$204,23),'⚡ COMMAND TRACKER'!$Y$5:$Y$204,0)),"") -> 0 | I26: =IFERROR(INDEX('⚡ COMMAND TRACKER'!$U$5:$U$204,MATCH(LARGE('⚡ COMMAND TRACKER'!$Y$5:$Y$204,23),'⚡ COMMAND TRACKER'!$Y$5:$Y$204,0)),"") -> 0 | J26: =IFERROR(INDEX('⚡ COMMAND TRACKER'!$X$5:$X$204,MATCH(LARGE('⚡ COMMAND TRACKER'!$Y$5:$Y$204,23),'⚡ COMMAND TRACKER'!$Y$5:$Y$204,0)),"") -> 0 | K26: =IFERROR(INDEX('⚡ COMMAND TRACKER'!$AC$5:$AC$204,MATCH(LARGE('⚡ COMMAND TRACKER'!$Y$5:$Y$204,23),'⚡ COMMAND TRACKER'!$Y$5:$Y$204,0)),"") -> 0 | L26: =IFERROR(IF(K26="","",K26-TODAY()),"") | M26: =IFERROR(INDEX('⚡ COMMAND TRACKER'!$AE$5:$AE$204,MATCH(LARGE('⚡ COMMAND TRACKER'!$Y$5:$Y$204,23),'⚡ COMMAND TRACKER'!$Y$5:$Y$204,0)),"") -> 0
A27: =IFERROR(INDEX('⚡ COMMAND TRACKER'!$AA$5:$AA$204,MATCH(LARGE('⚡ COMMAND TRACKER'!$Y$5:$Y$204,24),'⚡ COMMAND TRACKER'!$Y$5:$Y$204,0)),"") -> ⏳ WORKING | B27: =IFERROR(INDEX('⚡ COMMAND TRACKER'!$A$5:$A$204,MATCH(LARGE('⚡ COMMAND TRACKER'!$Y$5:$Y$204,24),'⚡ COMMAND TRACKER'!$Y$5:$Y$204,0)),"") -> 0 | C27: =IFERROR(INDEX('⚡ COMMAND TRACKER'!$E$5:$E$204,MATCH(LARGE('⚡ COMMAND TRACKER'!$Y$5:$Y$204,24),'⚡ COMMAND TRACKER'!$Y$5:$Y$204,0)),"") -> 0 | D27: =IFERROR(INDEX('⚡ COMMAND TRACKER'!$B$5:$B$204,MATCH(LARGE('⚡ COMMAND TRACKER'!$Y$5:$Y$204,24),'⚡ COMMAND TRACKER'!$Y$5:$Y$204,0)),"") -> 0 | E27: =IFERROR(INDEX('⚡ COMMAND TRACKER'!$H$5:$H$204,MATCH(LARGE('⚡ COMMAND TRACKER'!$Y$5:$Y$204,24),'⚡ COMMAND TRACKER'!$Y$5:$Y$204,0)),"") -> 0 | F27: =IFERROR(LARGE('⚡ COMMAND TRACKER'!$Y$5:$Y$204,24),"") -> 0 | G27: =IFERROR(INDEX('⚡ COMMAND TRACKER'!$Z$5:$Z$204,MATCH(LARGE('⚡ COMMAND TRACKER'!$Y$5:$Y$204,24),'⚡ COMMAND TRACKER'!$Y$5:$Y$204,0)),"") | H27: =IFERROR(INDEX('⚡ COMMAND TRACKER'!$T$5:$T$204,MATCH(LARGE('⚡ COMMAND TRACKER'!$Y$5:$Y$204,24),'⚡ COMMAND TRACKER'!$Y$5:$Y$204,0)),"") -> 0 | I27: =IFERROR(INDEX('⚡ COMMAND TRACKER'!$U$5:$U$204,MATCH(LARGE('⚡ COMMAND TRACKER'!$Y$5:$Y$204,24),'⚡ COMMAND TRACKER'!$Y$5:$Y$204,0)),"") -> 0 | J27: =IFERROR(INDEX('⚡ COMMAND TRACKER'!$X$5:$X$204,MATCH(LARGE('⚡ COMMAND TRACKER'!$Y$5:$Y$204,24),'⚡ COMMAND TRACKER'!$Y$5:$Y$204,0)),"") -> 0 | K27: =IFERROR(INDEX('⚡ COMMAND TRACKER'!$AC$5:$AC$204,MATCH(LARGE('⚡ COMMAND TRACKER'!$Y$5:$Y$204,24),'⚡ COMMAND TRACKER'!$Y$5:$Y$204,0)),"") -> 0 | L27: =IFERROR(IF(K27="","",K27-TODAY()),"") | M27: =IFERROR(INDEX('⚡ COMMAND TRACKER'!$AE$5:$AE$204,MATCH(LARGE('⚡ COMMAND TRACKER'!$Y$5:$Y$204,24),'⚡ COMMAND TRACKER'!$Y$5:$Y$204,0)),"") -> 0
A28: =IFERROR(INDEX('⚡ COMMAND TRACKER'!$AA$5:$AA$204,MATCH(LARGE('⚡ COMMAND TRACKER'!$Y$5:$Y$204,25),'⚡ COMMAND TRACKER'!$Y$5:$Y$204,0)),"") -> ⏳ WORKING | B28: =IFERROR(INDEX('⚡ COMMAND TRACKER'!$A$5:$A$204,MATCH(LARGE('⚡ COMMAND TRACKER'!$Y$5:$Y$204,25),'⚡ COMMAND TRACKER'!$Y$5:$Y$204,0)),"") -> 0 | C28: =IFERROR(INDEX('⚡ COMMAND TRACKER'!$E$5:$E$204,MATCH(LARGE('⚡ COMMAND TRACKER'!$Y$5:$Y$204,25),'⚡ COMMAND TRACKER'!$Y$5:$Y$204,0)),"") -> 0 | D28: =IFERROR(INDEX('⚡ COMMAND TRACKER'!$B$5:$B$204,MATCH(LARGE('⚡ COMMAND TRACKER'!$Y$5:$Y$204,25),'⚡ COMMAND TRACKER'!$Y$5:$Y$204,0)),"") -> 0 | E28: =IFERROR(INDEX('⚡ COMMAND TRACKER'!$H$5:$H$204,MATCH(LARGE('⚡ COMMAND TRACKER'!$Y$5:$Y$204,25),'⚡ COMMAND TRACKER'!$Y$5:$Y$204,0)),"") -> 0 | F28: =IFERROR(LARGE('⚡ COMMAND TRACKER'!$Y$5:$Y$204,25),"") -> 0 | G28: =IFERROR(INDEX('⚡ COMMAND TRACKER'!$Z$5:$Z$204,MATCH(LARGE('⚡ COMMAND TRACKER'!$Y$5:$Y$204,25),'⚡ COMMAND TRACKER'!$Y$5:$Y$204,0)),"") | H28: =IFERROR(INDEX('⚡ COMMAND TRACKER'!$T$5:$T$204,MATCH(LARGE('⚡ COMMAND TRACKER'!$Y$5:$Y$204,25),'⚡ COMMAND TRACKER'!$Y$5:$Y$204,0)),"") -> 0 | I28: =IFERROR(INDEX('⚡ COMMAND TRACKER'!$U$5:$U$204,MATCH(LARGE('⚡ COMMAND TRACKER'!$Y$5:$Y$204,25),'⚡ COMMAND TRACKER'!$Y$5:$Y$204,0)),"") -> 0 | J28: =IFERROR(INDEX('⚡ COMMAND TRACKER'!$X$5:$X$204,MATCH(LARGE('⚡ COMMAND TRACKER'!$Y$5:$Y$204,25),'⚡ COMMAND TRACKER'!$Y$5:$Y$204,0)),"") -> 0 | K28: =IFERROR(INDEX('⚡ COMMAND TRACKER'!$AC$5:$AC$204,MATCH(LARGE('⚡ COMMAND TRACKER'!$Y$5:$Y$204,25),'⚡ COMMAND TRACKER'!$Y$5:$Y$204,0)),"") -> 0 | L28: =IFERROR(IF(K28="","",K28-TODAY()),"") | M28: =IFERROR(INDEX('⚡ COMMAND TRACKER'!$AE$5:$AE$204,MATCH(LARGE('⚡ COMMAND TRACKER'!$Y$5:$Y$204,25),'⚡ COMMAND TRACKER'!$Y$5:$Y$204,0)),"") -> 0
A29: =IFERROR(INDEX('⚡ COMMAND TRACKER'!$AA$5:$AA$204,MATCH(LARGE('⚡ COMMAND TRACKER'!$Y$5:$Y$204,26),'⚡ COMMAND TRACKER'!$Y$5:$Y$204,0)),"") -> ⏳ WORKING | B29: =IFERROR(INDEX('⚡ COMMAND TRACKER'!$A$5:$A$204,MATCH(LARGE('⚡ COMMAND TRACKER'!$Y$5:$Y$204,26),'⚡ COMMAND TRACKER'!$Y$5:$Y$204,0)),"") -> 0 | C29: =IFERROR(INDEX('⚡ COMMAND TRACKER'!$E$5:$E$204,MATCH(LARGE('⚡ COMMAND TRACKER'!$Y$5:$Y$204,26),'⚡ COMMAND TRACKER'!$Y$5:$Y$204,0)),"") -> 0 | D29: =IFERROR(INDEX('⚡ COMMAND TRACKER'!$B$5:$B$204,MATCH(LARGE('⚡ COMMAND TRACKER'!$Y$5:$Y$204,26),'⚡ COMMAND TRACKER'!$Y$5:$Y$204,0)),"") -> 0 | E29: =IFERROR(INDEX('⚡ COMMAND TRACKER'!$H$5:$H$204,MATCH(LARGE('⚡ COMMAND TRACKER'!$Y$5:$Y$204,26),'⚡ COMMAND TRACKER'!$Y$5:$Y$204,0)),"") -> 0 | F29: =IFERROR(LARGE('⚡ COMMAND TRACKER'!$Y$5:$Y$204,26),"") -> 0 | G29: =IFERROR(INDEX('⚡ COMMAND TRACKER'!$Z$5:$Z$204,MATCH(LARGE('⚡ COMMAND TRACKER'!$Y$5:$Y$204,26),'⚡ COMMAND TRACKER'!$Y$5:$Y$204,0)),"") | H29: =IFERROR(INDEX('⚡ COMMAND TRACKER'!$T$5:$T$204,MATCH(LARGE('⚡ COMMAND TRACKER'!$Y$5:$Y$204,26),'⚡ COMMAND TRACKER'!$Y$5:$Y$204,0)),"") -> 0 | I29: =IFERROR(INDEX('⚡ COMMAND TRACKER'!$U$5:$U$204,MATCH(LARGE('⚡ COMMAND TRACKER'!$Y$5:$Y$204,26),'⚡ COMMAND TRACKER'!$Y$5:$Y$204,0)),"") -> 0 | J29: =IFERROR(INDEX('⚡ COMMAND TRACKER'!$X$5:$X$204,MATCH(LARGE('⚡ COMMAND TRACKER'!$Y$5:$Y$204,26),'⚡ COMMAND TRACKER'!$Y$5:$Y$204,0)),"") -> 0 | K29: =IFERROR(INDEX('⚡ COMMAND TRACKER'!$AC$5:$AC$204,MATCH(LARGE('⚡ COMMAND TRACKER'!$Y$5:$Y$204,26),'⚡ COMMAND TRACKER'!$Y$5:$Y$204,0)),"") -> 0 | L29: =IFERROR(IF(K29="","",K29-TODAY()),"") | M29: =IFERROR(INDEX('⚡ COMMAND TRACKER'!$AE$5:$AE$204,MATCH(LARGE('⚡ COMMAND TRACKER'!$Y$5:$Y$204,26),'⚡ COMMAND TRACKER'!$Y$5:$Y$204,0)),"") -> 0
A30: =IFERROR(INDEX('⚡ COMMAND TRACKER'!$AA$5:$AA$204,MATCH(LARGE('⚡ COMMAND TRACKER'!$Y$5:$Y$204,27),'⚡ COMMAND TRACKER'!$Y$5:$Y$204,0)),"") -> ⏳ WORKING | B30: =IFERROR(INDEX('⚡ COMMAND TRACKER'!$A$5:$A$204,MATCH(LARGE('⚡ COMMAND TRACKER'!$Y$5:$Y$204,27),'⚡ COMMAND TRACKER'!$Y$5:$Y$204,0)),"") -> 0 | C30: =IFERROR(INDEX('⚡ COMMAND TRACKER'!$E$5:$E$204,MATCH(LARGE('⚡ COMMAND TRACKER'!$Y$5:$Y$204,27),'⚡ COMMAND TRACKER'!$Y$5:$Y$204,0)),"") -> 0 | D30: =IFERROR(INDEX('⚡ COMMAND TRACKER'!$B$5:$B$204,MATCH(LARGE('⚡ COMMAND TRACKER'!$Y$5:$Y$204,27),'⚡ COMMAND TRACKER'!$Y$5:$Y$204,0)),"") -> 0 | E30: =IFERROR(INDEX('⚡ COMMAND TRACKER'!$H$5:$H$204,MATCH(LARGE('⚡ COMMAND TRACKER'!$Y$5:$Y$204,27),'⚡ COMMAND TRACKER'!$Y$5:$Y$204,0)),"") -> 0 | F30: =IFERROR(LARGE('⚡ COMMAND TRACKER'!$Y$5:$Y$204,27),"") -> 0 | G30: =IFERROR(INDEX('⚡ COMMAND TRACKER'!$Z$5:$Z$204,MATCH(LARGE('⚡ COMMAND TRACKER'!$Y$5:$Y$204,27),'⚡ COMMAND TRACKER'!$Y$5:$Y$204,0)),"") | H30: =IFERROR(INDEX('⚡ COMMAND TRACKER'!$T$5:$T$204,MATCH(LARGE('⚡ COMMAND TRACKER'!$Y$5:$Y$204,27),'⚡ COMMAND TRACKER'!$Y$5:$Y$204,0)),"") -> 0 | I30: =IFERROR(INDEX('⚡ COMMAND TRACKER'!$U$5:$U$204,MATCH(LARGE('⚡ COMMAND TRACKER'!$Y$5:$Y$204,27),'⚡ COMMAND TRACKER'!$Y$5:$Y$204,0)),"") -> 0 | J30: =IFERROR(INDEX('⚡ COMMAND TRACKER'!$X$5:$X$204,MATCH(LARGE('⚡ COMMAND TRACKER'!$Y$5:$Y$204,27),'⚡ COMMAND TRACKER'!$Y$5:$Y$204,0)),"") -> 0 | K30: =IFERROR(INDEX('⚡ COMMAND TRACKER'!$AC$5:$AC$204,MATCH(LARGE('⚡ COMMAND TRACKER'!$Y$5:$Y$204,27),'⚡ COMMAND TRACKER'!$Y$5:$Y$204,0)),"") -> 0 | L30: =IFERROR(IF(K30="","",K30-TODAY()),"") | M30: =IFERROR(INDEX('⚡ COMMAND TRACKER'!$AE$5:$AE$204,MATCH(LARGE('⚡ COMMAND TRACKER'!$Y$5:$Y$204,27),'⚡ COMMAND TRACKER'!$Y$5:$Y$204,0)),"") -> 0
